<?xml version="1.0" encoding="utf-8" ?>
<!-- This URDF was automatically created by SolidWorks to URDF Exporter! Originally created by Stephen Brawner (brawner@gmail.com) 
     Commit Version: 1.6.0-4-g7f85cfe  Build Version: 1.6.7995.38578
     For more information, please see http://wiki.ros.org/sw_urdf_exporter -->
<robot name="air_dual_arm_description">
    <link name="base_link">
        <inertial>
            <origin xyz="-0.00671332757855916 0.437069422553028 -0.00349142497007035" rpy="0 0 0" />
            <mass value="6.75653562194786" />
            <inertia ixx="0.968920953957115" ixy="-0.0158745347568794" ixz="0.000438931552270688" iyy="0.262307848620789" iyz="0.0167493441759554" izz="1.01905987425296" />
        </inertial>
        <visual>
            <origin xyz="0 0 0" rpy="0 0 0" />
            <geometry>
                <mesh filename="package://air_dual_arm_description/meshes/base_link.STL" />
            </geometry>
            <material name="">
                <color rgba="0.792156862745098 0.819607843137255 0.933333333333333 1" />
            </material>
        </visual>
        <collision>
            <origin xyz="0 0 0" rpy="0 0 0" />
            <geometry>
                <mesh filename="package://air_dual_arm_description/meshes/base_link.STL" />
            </geometry>
        </collision>
    </link>
    <link name="camera_link">
        <inertial>
            <origin xyz="0 0 " rpy="0 0 0" />
        </inertial>
    </link>
    <joint name="virtual_camera_joint" type="fixed">
        <origin xyz="-0.0138 0.0548 1.0685" rpy="0 0.45 -0.1605" />
        <parent link="base_link" />
        <child link="camera_link" />
        <axis xyz="0 0 0" />
    </joint>
    <link name="s1">
        <inertial>
            <origin xyz="-0.0565855661773653 -1.47432999124675E-05 0.0503451976338493" rpy="0 0 0" />
            <mass value="0.542684124579144" />
            <inertia ixx="0.000345761092952399" ixy="-3.24050500600486E-07" ixz="1.50683178516403E-07" iyy="0.000778022471193682" iyz="1.07326375799424E-08" izz="0.000776671252305068" />
        </inertial>
        <visual>
            <origin xyz="0 0 0" rpy="0 0 0" />
            <geometry>
                <mesh filename="package://air_description/meshes/s1.STL" />
            </geometry>
            <material name="">
                <color rgba="0.792156862745098 0.819607843137255 0.933333333333333 1" />
            </material>
        </visual>
        <collision>
            <origin xyz="0 0 0" rpy="0 0 0" />
            <geometry>
                <mesh filename="package://air_description/meshes/s1.STL" />
            </geometry>
        </collision>
    </link>
    <joint name="s1j" type="revolute">
        <origin xyz="0 -0.1455 1.2" rpy="1.5708 0 0" />
        <parent link="base_link" />
        <child link="s1" />
        <axis xyz="0 0 1" />
        <limit lower="-0.78" upper="0.78" effort="0" velocity="0.35" />
    </joint>
    <link name="s2">
        <inertial>
            <origin xyz="0.0265368019978267 -0.0360762146328593 0.00202591662662588" rpy="0 0 0" />
            <mass value="0.0397003268136184" />
            <inertia ixx="1.77539568949169E-05" ixy="-5.49265597337707E-08" ixz="4.46961963342789E-21" iyy="9.62749691816005E-06" iyz="5.5659379414233E-21" izz="1.53865784423673E-05" />
        </inertial>
        <visual>
            <origin xyz="0 0 0" rpy="0 0 0" />
            <geometry>
                <mesh filename="package://air_description/meshes/s2.STL" />
            </geometry>
            <material name="">
                <color rgba="0.792156862745098 0.819607843137255 0.933333333333333 1" />
            </material>
        </visual>
        <collision>
            <origin xyz="0 0 0" rpy="0 0 0" />
            <geometry>
                <mesh filename="package://air_description/meshes/s2.STL" />
            </geometry>
        </collision>
    </link>
    <joint name="s2j" type="revolute">
        <origin xyz="0 0 0.05" rpy="0 0 0" />
        <parent link="s1" />
        <child link="s2" />
        <axis xyz="-1 0 0" />
        <limit lower="0" upper="1.57" effort="0" velocity="0.35" />
    </joint>
    <link name="s3">
        <inertial>
            <origin xyz="-0.0307852686146159 -0.106762715233885 -0.00285680761161178" rpy="0 0 0" />
            <mass value="0.69346525440976" />
            <inertia ixx="0.000632226154715784" ixy="3.3846916742775E-06" ixz="-2.03216958615076E-06" iyy="0.000203793561582271" iyz="-7.69131798756883E-08" izz="0.000626858789980171" />
        </inertial>
        <visual>
            <origin xyz="0 0 0" rpy="0 0 0" />
            <geometry>
                <mesh filename="package://air_description/meshes/s3.STL" />
            </geometry>
            <material name="">
                <color rgba="0.792156862745098 0.819607843137255 0.933333333333333 1" />
            </material>
        </visual>
        <collision>
            <origin xyz="0 0 0" rpy="0 0 0" />
            <geometry>
                <mesh filename="package://air_description/meshes/s3.STL" />
            </geometry>
        </collision>
    </link>
    <joint name="s3j" type="revolute">
        <origin xyz="-0.00345 -0.06 0.0036" rpy="0 0 0" />
        <parent link="s2" />
        <child link="s3" />
        <axis xyz="0 -1 0" />
        <limit lower="-1.57" upper="1.57" effort="0" velocity="0.35" />
    </joint>
    <link name="e">
        <inertial>
            <origin xyz="0.133914313079551 0.0397090138567681 -0.00135370354868536" rpy="0 0 0" />
            <mass value="0.524484949455585" />
            <inertia ixx="0.000164098535625993" ixy="-0.00011555456704967" ixz="-1.49937999308697E-06" iyy="0.000491486729879123" iyz="5.4210279008361E-06" izz="0.000537801635705856" />
        </inertial>
        <visual>
            <origin xyz="0 0 0" rpy="0 0 0" />
            <geometry>
                <mesh filename="package://air_description/meshes/e.STL" />
            </geometry>
            <material name="">
                <color rgba="0.792156862745098 0.819607843137255 0.933333333333333 1" />
            </material>
        </visual>
        <collision>
            <origin xyz="0 0 0" rpy="0 0 0" />
            <geometry>
                <mesh filename="package://air_description/meshes/e.STL" />
            </geometry>
        </collision>
    </link>
    <joint name="ej" type="revolute">
        <origin xyz="-0.005 -0.2835 0" rpy="0 0 -0.28935" />
        <parent link="s3" />
        <child link="e" />
        <axis xyz="0 0 1" />
        <limit lower="-1.4" upper="0.14" effort="0" velocity="0.13" />
    </joint>
    <link name="roll">
        <inertial>
            <origin xyz="2.11649564541005E-08 2.17253527112771E-08 -5.72361158468482E-10" rpy="0 0 0" />
            <mass value="0.0123350072540482" />
            <inertia ixx="5.73140316108075E-06" ixy="2.39610064059149E-12" ixz="2.37221429275288E-12" iyy="3.0133459248538E-06" iyz="-2.51281711383088E-12" izz="3.01335111374677E-06" />
        </inertial>
        <visual>
            <origin xyz="0 0 0" rpy="0 0 0" />
            <geometry>
                <mesh filename="package://air_description/meshes/roll.STL" />
            </geometry>
            <material name="">
                <color rgba="0.792156862745098 0.819607843137255 0.933333333333333 1" />
            </material>
        </visual>
        <collision>
            <origin xyz="0 0 0" rpy="0 0 0" />
            <geometry>
                <mesh filename="package://air_description/meshes/roll.STL" />
            </geometry>
        </collision>
    </link>
    <joint name="rollj" type="revolute">
        <origin xyz="0.25159 0.0749 0" rpy="-1.5708 0 -2.8522" />
        <parent link="e" />
        <child link="roll" />
        <axis xyz="0 0.70711 0.70711" />
        <limit lower="-0.26" upper="0.26" effort="0" velocity="0.09" />
    </joint>
    <link name="pitch">
        <inertial>
            <origin xyz="0.0286089165171641 -0.000144661566694015 0.009855465038871" rpy="0 0 0" />
            <mass value="0.0576090249075869" />
            <inertia ixx="7.09168260696957E-05" ixy="-9.04854271559607E-09" ixz="-9.02484498992207E-09" iyy="3.68466285330398E-05" iyz="-3.7654782496613E-07" izz="3.68466243102646E-05" />
        </inertial>
        <visual>
            <origin xyz="0 0 0" rpy="0 0 0" />
            <geometry>
                <mesh filename="package://air_description/meshes/pitch.STL" />
            </geometry>
            <material name="">
                <color rgba="0.792156862745098 0.819607843137255 0.933333333333333 1" />
            </material>
        </visual>
        <collision>
            <origin xyz="0 0 0" rpy="0 0 0" />
            <geometry>
                <mesh filename="package://air_description/meshes/pitch.STL" />
            </geometry>
        </collision>
    </link>
    <joint name="pitchj" type="revolute">
        <origin xyz="0 0.01 0" rpy="-1.5708 0 3.1416" />
        <parent link="roll" />
        <child link="pitch" />
        <axis xyz="0 0.70711 -0.70711" />
        <limit lower="-0.26" upper="0.26" effort="0" velocity="0.09" />
    </joint>
    <joint name="yawj" type="revolute">
        <origin rpy="0 -1.57079632679 3.14159265359" xyz="0.0464 0 0.01 " />
        <parent link="pitch" />
        <child link="root_link" />
        <axis xyz="0 0 1" />
        <limit lower="-3.0" upper="3.0" effort="0" velocity="1.75" />
    </joint>
    <link name="root_link" />
    <joint name="virtual_root_joint" type="fixed">
        <origin rpy="0 0 0" xyz="0 0 0 " />
        <parent link="root_link" />
        <child link="qbhand_base_link" />
    </joint>
    <link name="qbhand_base_link">
        <inertial>
            <mass value="0.45" />
            <origin rpy="0 0 0" xyz="0.0030 -0.0449 0.0135" />
            <inertia ixx="0.00045" ixy="0.0" ixz="0.0" iyy="0.0006" iyz="0.0" izz="0.00025" />
        </inertial>
        <visual>
            <origin rpy="0 0 0" xyz="0 0 0" />
            <geometry>
                <mesh filename="package://qb_hand_description/meshes/flange_iso_04.stl" scale="0.001 0.001 0.001" />
            </geometry>
            <material name="qbhand/base" />
        </visual>
        <collision>
            <origin rpy="0 0 0" xyz="0 0 0" />
            <geometry>
                <mesh filename="package://qb_hand_description/meshes/flange_iso_04.stl" scale="0.001 0.001 0.001" />
            </geometry>
        </collision>
    </link>
    <joint name="qbhand_palm_fixed_joint" type="fixed">
        <origin rpy="1.57 0 0" xyz="-0.0045 0.0145 0.144" />
        <parent link="qbhand_base_link" />
        <child link="qbhand_palm_link" />
    </joint>
    <link name="qbhand_palm_link">
        <inertial>
            <mass value="0.45" />
            <origin rpy="0 0 0" xyz="0.0030 -0.0449 0.0135" />
            <inertia ixx="0.00045" ixy="0.0" ixz="0.0" iyy="0.0006" iyz="0.0" izz="0.00025" />
        </inertial>
        <visual>
            <origin rpy="0 0 0" xyz="0 0 0" />
            <geometry>
                <mesh filename="package://qb_hand_description/meshes/palm_pinch_r.stl" scale="0.001 0.001 0.001" />
            </geometry>
            <material name="qbhand/palm" />
        </visual>
        <collision>
            <origin rpy="0 0 0" xyz="0 0 0" />
            <geometry>
                <mesh filename="package://qb_hand_description/meshes/palm_pinch_r.stl" scale="0.001 0.001 0.001" />
            </geometry>
        </collision>
    </link>
    <joint name="qbhand_synergy_joint" type="revolute">
        <origin rpy="0 0 0" xyz="0 0 0" />
        <parent link="qbhand_palm_link" />
        <child link="qbhand_synergy_tendon_virtual_link" />
        <axis xyz="0 0 1" />
        <dynamics damping="0.0" friction="0.0" />
        <limit effort="100" lower="0.0" upper="1.0" velocity="100" />
    </joint>
    <transmission name="qbhand_synergy_transmission">
        <type>transmission_interface/qbMoveTransmission</type>
        <joint name="qbhand_synergy_joint">
            <hardwareInterface>hardware_interface/EffortJointInterface</hardwareInterface>
        </joint>
        <actuator name="qbhand_synergy_joint">
            <hardwareInterface>hardware_interface/EffortJointInterface</hardwareInterface>
        </actuator>
    </transmission>
    <link name="qbhand_synergy_tendon_virtual_link">
        <inertial>
            <origin rpy="0 0 0" xyz="0 0 0" />
            <mass value="1e-4" />
            <inertia ixx="1e-9" ixy="0.0" ixz="0.0" iyy="1e-9" iyz="0.0" izz="1e-9" />
        </inertial>
    </link>
    <joint name="qbhand_thumb_knuckle_joint" type="revolute">
        <origin rpy="-1.57 3.14 0.0" xyz="-0.044 -0.0465 -0.002" />
        <parent link="qbhand_palm_link" />
        <child link="qbhand_thumb_knuckle_link" />
        <axis xyz="0 0 -1" />
        <dynamics damping="0.0" friction="0.0" />
        <limit effort="100" lower="0.0" upper="1.571" velocity="100" />
        <mimic joint="qbhand_synergy_joint" multiplier="1" />
        <!--mimic joint="qbhand_synergy_joint" multiplier="2.542"/-->
    </joint>
    <transmission name="qbhand_transmission">
        <type>transmission_interface/qbMoveTransmission</type>
        <joint name="qbhand_thumb_knuckle_joint">
            <hardwareInterface>hardware_interface/EffortJointInterface</hardwareInterface>
        </joint>
        <actuator name="qbhand_thumb_knuckle_joint">
            <hardwareInterface>hardware_interface/EffortJointInterface</hardwareInterface>
        </actuator>
    </transmission>
    <link name="qbhand_thumb_knuckle_link">
        <inertial>
            <mass value="0.01" />
            <origin rpy="0 0 0" xyz="1.3071561e-02 -2.7357764e-03 6.4347823e-04" />
            <inertia ixx="3.5865978e-07" ixy="2.0944224e-07" ixz="-6.8657569e-08" iyy="1.3885564e-06" iyz="3.2170608e-08" izz="1.3571203e-06" />
        </inertial>
        <visual>
            <origin rpy="0 0 0" xyz="0 0 0" />
            <geometry>
                <mesh filename="package://qb_hand_description/meshes/ph_thumb_r.stl" scale="0.001 0.001 0.001" />
            </geometry>
            <material name="qbhand/knuckle" />
        </visual>
        <collision>
            <origin rpy="0 0 0" xyz="0 0 0" />
            <geometry>
                <mesh filename="package://qb_hand_description/meshes/ph_thumb_r_collision.stl" scale="0.001 0.001 0.001" />
            </geometry>
        </collision>
    </link>
    <joint name="qbhand_thumb_proximal_joint" type="revolute">
        <origin rpy="-1.1415 0.0 0.0" xyz="0.0255 -0.0038 -0.00012" />
        <parent link="qbhand_thumb_knuckle_link" />
        <child link="qbhand_thumb_proximal_virtual_link" />
        <axis xyz="0 0 -1" />
        <dynamics damping="0.0" friction="0.0" />
        <limit effort="100" lower="0.0" upper="0.785" velocity="100" />
        <mimic joint="qbhand_synergy_joint" multiplier="0.785" />
    </joint>
    <transmission name="qbhand_transmission">
        <type>transmission_interface/qbMoveTransmission</type>
        <joint name="qbhand_thumb_proximal_joint">
            <hardwareInterface>hardware_interface/EffortJointInterface</hardwareInterface>
        </joint>
        <actuator name="qbhand_thumb_proximal_joint">
            <hardwareInterface>hardware_interface/EffortJointInterface</hardwareInterface>
        </actuator>
    </transmission>
    <link name="qbhand_thumb_proximal_virtual_link">
        <inertial>
            <origin rpy="0 0 0" xyz="0 0 0" />
            <mass value="1e-4" />
            <inertia ixx="1e-9" ixy="0.0" ixz="0.0" iyy="1e-9" iyz="0.0" izz="1e-9" />
        </inertial>
    </link>
    <joint name="qbhand_thumb_proximal_virtual_joint" type="revolute">
        <origin rpy="0 0 0" xyz="0.013 0 0" />
        <parent link="qbhand_thumb_proximal_virtual_link" />
        <child link="qbhand_thumb_proximal_link" />
        <axis xyz="0 0 -1" />
        <dynamics damping="0.0" friction="0.0" />
        <limit effort="100" lower="0.0" upper="0.785" velocity="100" />
        <mimic joint="qbhand_thumb_proximal_joint" multiplier="1.0" />
    </joint>
    <transmission name="qbhand_transmission">
        <type>transmission_interface/qbMoveTransmission</type>
        <joint name="qbhand_thumb_proximal_virtual_joint">
            <hardwareInterface>hardware_interface/EffortJointInterface</hardwareInterface>
        </joint>
        <actuator name="qbhand_thumb_proximal_virtual_joint">
            <hardwareInterface>hardware_interface/EffortJointInterface</hardwareInterface>
        </actuator>
    </transmission>
    <link name="qbhand_thumb_proximal_link">
        <inertial>
            <mass value="0.0063" />
            <origin rpy="0 0 0" xyz="4.7601567e-03 -1.3786947e-03 0.0" />
            <inertia ixx="1.8024201e-07" ixy="5.756798e-09" ixz="0.0" iyy="2.3516266e-07" iyz="0.0" izz="2.691504e-07" />
        </inertial>
        <visual>
            <origin rpy="0 0 0" xyz="0 0 0" />
            <geometry>
                <mesh filename="package://qb_hand_description/meshes/ph_short.stl" scale="0.001 0.001 0.001" />
            </geometry>
            <material name="qbhand/proximal" />
        </visual>
        <collision>
            <origin rpy="0 0 0" xyz="0 0 0" />
            <geometry>
                <mesh filename="package://qb_hand_description/meshes/ph_short_collision.stl" scale="0.001 0.001 0.001" />
            </geometry>
        </collision>
    </link>
    <joint name="qbhand_thumb_distal_joint" type="revolute">
        <origin rpy="0 0 0" xyz="0.009 0 0" />
        <parent link="qbhand_thumb_proximal_link" />
        <child link="qbhand_thumb_distal_virtual_link" />
        <axis xyz="0 0 -1" />
        <dynamics damping="0.0" friction="0.0" />
        <limit effort="100" lower="0.0" upper="0.785" velocity="100" />
        <mimic joint="qbhand_synergy_joint" multiplier="0.785" />
    </joint>
    <transmission name="qbhand_transmission">
        <type>transmission_interface/qbMoveTransmission</type>
        <joint name="qbhand_thumb_distal_joint">
            <hardwareInterface>hardware_interface/EffortJointInterface</hardwareInterface>
        </joint>
        <actuator name="qbhand_thumb_distal_joint">
            <hardwareInterface>hardware_interface/EffortJointInterface</hardwareInterface>
        </actuator>
    </transmission>
    <link name="qbhand_thumb_distal_virtual_link">
        <inertial>
            <origin rpy="0 0 0" xyz="0 0 0" />
            <mass value="1e-4" />
            <inertia ixx="1e-9" ixy="0.0" ixz="0.0" iyy="1e-9" iyz="0.0" izz="1e-9" />
        </inertial>
    </link>
    <joint name="qbhand_thumb_distal_virtual_joint" type="revolute">
        <origin rpy="0 0 0" xyz="0.013 0 0" />
        <parent link="qbhand_thumb_distal_virtual_link" />
        <child link="qbhand_thumb_distal_link" />
        <axis xyz="0 0 -1" />
        <dynamics damping="0.0" friction="0.0" />
        <limit effort="100" lower="0.0" upper="0.785" velocity="100" />
        <mimic joint="qbhand_thumb_distal_joint" multiplier="1.0" />
    </joint>
    <transmission name="qbhand_transmission">
        <type>transmission_interface/qbMoveTransmission</type>
        <joint name="qbhand_thumb_distal_virtual_joint">
            <hardwareInterface>hardware_interface/EffortJointInterface</hardwareInterface>
        </joint>
        <actuator name="qbhand_thumb_distal_virtual_joint">
            <hardwareInterface>hardware_interface/EffortJointInterface</hardwareInterface>
        </actuator>
    </transmission>
    <gazebo reference="qbhand_thumb_distal_virtual_joint">
        <!-- TODO: add other Gazebo Joint properties (http://sdformat.org/spec?elem=joint) -->
        <plugin name="gazebo_ros_control">
            <robotNamespace>/</robotNamespace>
        </plugin>
    </gazebo>
    <link name="qbhand_thumb_distal_link">
        <inertial>
            <mass value="0.009" />
            <origin rpy="0 0 0" xyz="8.8025467e-03 -1.7219289e-03 0.0" />
            <inertia ixx="2.6586142e-07" ixy="1.2416847e-08" ixz="0.0" iyy="5.9935767e-07" iyz="0.0" izz="6.6781963e-07" />
        </inertial>
        <visual>
            <origin rpy="0 0 0" xyz="0 0 0" />
            <geometry>
                <mesh filename="package://qb_hand_description/meshes/ph_distal.stl" scale="0.001 0.001 0.001" />
            </geometry>
            <material name="qbhand/distal" />
        </visual>
        <collision>
            <origin rpy="0 0 0" xyz="0 0 0" />
            <geometry>
                <mesh filename="package://qb_hand_description/meshes/ph_distal_collision.stl" scale="0.001 0.001 0.001" />
            </geometry>
        </collision>
    </link>
    <gazebo reference="qbhand_thumb_distal_link">
        <self_collide>1</self_collide>
        <!-- TODO: add other Gazebo Link properties (http://sdformat.org/spec?elem=link) -->
        <!--      <collision>-->
        <!--        <surface>-->
        <!--          <contact>-->
        <!--            <ode>-->
        <!--              <kp>1.0</kp>-->
        <!--              <kd>0.01</kd>-->
        <!--              <max_vel>0.0</max_vel>-->
        <!--              <min_depth>0.001</min_depth>-->
        <!--            </ode>-->
        <!--          </contact>-->
        <!--          <friction>-->
        <!--            <ode>-->
        <!--              <mu>0.9</mu>-->
        <!--              <mu2>0.9</mu2>-->
        <!--            </ode>-->
        <!--          </friction>-->
        <!--        </surface>-->
        <!--      </collision>-->
    </gazebo>
    <joint name="qbhand_index_knuckle_joint" type="revolute">
        <origin rpy="0 0 1.57" xyz="-0.02 -0.007 0.014" />
        <parent link="qbhand_palm_link" />
        <child link="qbhand_index_knuckle_link" />
        <axis xyz="0 0 -1" />
        <dynamics damping="0.0" friction="0.0" />
        <limit effort="100" lower="-0.524" upper="0.524" velocity="100" />
        <mimic joint="qbhand_synergy_joint" multiplier="-0.2" />
    </joint>
    <transmission name="qbhand_transmission">
        <type>transmission_interface/qbMoveTransmission</type>
        <joint name="qbhand_index_knuckle_joint">
            <hardwareInterface>hardware_interface/EffortJointInterface</hardwareInterface>
        </joint>
        <actuator name="qbhand_index_knuckle_joint">
            <hardwareInterface>hardware_interface/EffortJointInterface</hardwareInterface>
        </actuator>
    </transmission>
    <gazebo reference="qbhand_index_knuckle_joint">
        <!-- TODO: add other Gazebo Joint properties (http://sdformat.org/spec?elem=joint) -->
    </gazebo>
    <link name="qbhand_index_knuckle_link">
        <inertial>
            <mass value="0.0095" />
            <origin rpy="0 0 0" xyz="4.2753603e-04  0.0 -1.4321738e-03" />
            <inertia ixx="6.4337303e-07" ixy="0.0" ixz="-3.9373913e-08" iyy="1.1253771e-06" iyz="0.0" izz="7.2336948e-07" />
        </inertial>
        <visual>
            <origin rpy="0 0 0" xyz="0 0 0" />
            <geometry>
                <mesh filename="package://qb_hand_description/meshes/ph_knuckle.stl" scale="0.001 0.001 0.001" />
            </geometry>
            <material name="qbhand/knuckle" />
        </visual>
        <collision>
            <origin rpy="0 0 0" xyz="0 0 0" />
            <geometry>
                <mesh filename="package://qb_hand_description/meshes/ph_knuckle_collision.stl" scale="0.001 0.001 0.001" />
            </geometry>
        </collision>
    </link>
    <gazebo reference="qbhand_index_knuckle_link">
        <self_collide>1</self_collide>
        <!-- TODO: add other Gazebo Link properties (http://sdformat.org/spec?elem=link) -->
        <!--      <collision>-->
        <!--        <surface>-->
        <!--          <contact>-->
        <!--            <ode>-->
        <!--              <kp>1.0</kp>-->
        <!--              <kd>0.01</kd>-->
        <!--              <max_vel>0.0</max_vel>-->
        <!--              <min_depth>0.001</min_depth>-->
        <!--            </ode>-->
        <!--          </contact>-->
        <!--          <friction>-->
        <!--            <ode>-->
        <!--              <mu>0.9</mu>-->
        <!--              <mu2>0.9</mu2>-->
        <!--            </ode>-->
        <!--          </friction>-->
        <!--        </surface>-->
        <!--      </collision>-->
    </gazebo>
    <joint name="qbhand_index_proximal_joint" type="revolute">
        <origin rpy="1.57 0 0" xyz="0.009 0 0" />
        <parent link="qbhand_index_knuckle_link" />
        <child link="qbhand_index_proximal_virtual_link" />
        <axis xyz="0 0 -1" />
        <dynamics damping="0.0" friction="0.0" />
        <limit effort="100" lower="0.0" upper="0.785" velocity="100" />
        <mimic joint="qbhand_synergy_joint" multiplier="0.785" />
    </joint>
    <transmission name="qbhand_transmission">
        <type>transmission_interface/qbMoveTransmission</type>
        <joint name="qbhand_index_proximal_joint">
            <hardwareInterface>hardware_interface/EffortJointInterface</hardwareInterface>
        </joint>
        <actuator name="qbhand_index_proximal_joint">
            <hardwareInterface>hardware_interface/EffortJointInterface</hardwareInterface>
        </actuator>
    </transmission>
    <gazebo reference="qbhand_index_proximal_joint">
        <!-- TODO: add other Gazebo Joint properties (http://sdformat.org/spec?elem=joint) -->
    </gazebo>
    <link name="qbhand_index_proximal_virtual_link">
        <inertial>
            <origin rpy="0 0 0" xyz="0 0 0" />
            <mass value="1e-4" />
            <inertia ixx="1e-9" ixy="0.0" ixz="0.0" iyy="1e-9" iyz="0.0" izz="1e-9" />
        </inertial>
    </link>
    <joint name="qbhand_index_proximal_virtual_joint" type="revolute">
        <origin rpy="0 0 0" xyz="0.013 0 0" />
        <parent link="qbhand_index_proximal_virtual_link" />
        <child link="qbhand_index_proximal_link" />
        <axis xyz="0 0 -1" />
        <dynamics damping="0.0" friction="0.0" />
        <limit effort="100" lower="0.0" upper="0.785" velocity="100" />
        <mimic joint="qbhand_index_proximal_joint" multiplier="1.0" />
    </joint>
    <transmission name="qbhand_transmission">
        <type>transmission_interface/qbMoveTransmission</type>
        <joint name="qbhand_index_proximal_virtual_joint">
            <hardwareInterface>hardware_interface/EffortJointInterface</hardwareInterface>
        </joint>
        <actuator name="qbhand_index_proximal_virtual_joint">
            <hardwareInterface>hardware_interface/EffortJointInterface</hardwareInterface>
        </actuator>
    </transmission>
    <gazebo reference="qbhand_index_proximal_virtual_joint">
        <!-- TODO: add other Gazebo Joint properties (http://sdformat.org/spec?elem=joint) -->
    </gazebo>
    <link name="qbhand_index_proximal_link">
        <inertial>
            <mass value="0.0082" />
            <origin rpy="0 0 0" xyz="8.7707437e-03 -1.7863138e-03 0.0" />
            <inertia ixx="2.2722068e-07" ixy="1.1586053e-08" ixz="0.0" iyy="5.5947233e-07" iyz="0.0" izz="5.9562195e-07" />
        </inertial>
        <visual>
            <origin rpy="0 0 0" xyz="0 0 0" />
            <geometry>
                <mesh filename="package://qb_hand_description/meshes/ph_medium.stl" scale="0.001 0.001 0.001" />
            </geometry>
            <material name="qbhand/proximal" />
        </visual>
        <collision>
            <origin rpy="0 0 0" xyz="0 0 0" />
            <geometry>
                <mesh filename="package://qb_hand_description/meshes/ph_medium_collision.stl" scale="0.001 0.001 0.001" />
            </geometry>
        </collision>
    </link>
    <gazebo reference="qbhand_index_proximal_link">
        <self_collide>1</self_collide>
        <!-- TODO: add other Gazebo Link properties (http://sdformat.org/spec?elem=link) -->
        <!--      <collision>-->
        <!--        <surface>-->
        <!--          <contact>-->
        <!--            <ode>-->
        <!--              <kp>1.0</kp>-->
        <!--              <kd>0.01</kd>-->
        <!--              <max_vel>0.0</max_vel>-->
        <!--              <min_depth>0.001</min_depth>-->
        <!--            </ode>-->
        <!--          </contact>-->
        <!--          <friction>-->
        <!--            <ode>-->
        <!--              <mu>0.9</mu>-->
        <!--              <mu2>0.9</mu2>-->
        <!--            </ode>-->
        <!--          </friction>-->
        <!--        </surface>-->
        <!--      </collision>-->
    </gazebo>
    <joint name="qbhand_index_middle_joint" type="revolute">
        <origin rpy="0 0 0" xyz="0.017 0 0" />
        <parent link="qbhand_index_proximal_link" />
        <child link="qbhand_index_middle_virtual_link" />
        <axis xyz="0 0 -1" />
        <dynamics damping="0.0" friction="0.0" />
        <limit effort="100" lower="0.0" upper="0.785" velocity="100" />
        <mimic joint="qbhand_synergy_joint" multiplier="0.785" />
    </joint>
    <transmission name="qbhand_transmission">
        <type>transmission_interface/qbMoveTransmission</type>
        <joint name="qbhand_index_middle_joint">
            <hardwareInterface>hardware_interface/EffortJointInterface</hardwareInterface>
        </joint>
        <actuator name="qbhand_index_middle_joint">
            <hardwareInterface>hardware_interface/EffortJointInterface</hardwareInterface>
        </actuator>
    </transmission>
    <gazebo reference="qbhand_index_middle_joint">
        <!-- TODO: add other Gazebo Joint properties (http://sdformat.org/spec?elem=joint) -->
    </gazebo>
    <link name="qbhand_index_middle_virtual_link">
        <inertial>
            <origin rpy="0 0 0" xyz="0 0 0" />
            <mass value="1e-4" />
            <inertia ixx="1e-9" ixy="0.0" ixz="0.0" iyy="1e-9" iyz="0.0" izz="1e-9" />
        </inertial>
    </link>
    <joint name="qbhand_index_middle_virtual_joint" type="revolute">
        <origin rpy="0 0 0" xyz="0.013 0 0" />
        <parent link="qbhand_index_middle_virtual_link" />
        <child link="qbhand_index_middle_link" />
        <axis xyz="0 0 -1" />
        <dynamics damping="0.0" friction="0.0" />
        <limit effort="100" lower="0.0" upper="0.785" velocity="100" />
        <mimic joint="qbhand_index_middle_joint" multiplier="1.0" />
    </joint>
    <transmission name="qbhand_transmission">
        <type>transmission_interface/qbMoveTransmission</type>
        <joint name="qbhand_index_middle_virtual_joint">
            <hardwareInterface>hardware_interface/EffortJointInterface</hardwareInterface>
        </joint>
        <actuator name="qbhand_index_middle_virtual_joint">
            <hardwareInterface>hardware_interface/EffortJointInterface</hardwareInterface>
        </actuator>
    </transmission>
    <gazebo reference="qbhand_index_middle_virtual_joint">
        <!-- TODO: add other Gazebo Joint properties (http://sdformat.org/spec?elem=joint) -->
    </gazebo>
    <link name="qbhand_index_middle_link">
        <inertial>
            <mass value="0.0063" />
            <origin rpy="0 0 0" xyz="4.7601567e-03 -1.3786947e-03 0.0" />
            <inertia ixx="1.8024201e-07" ixy="5.756798e-09" ixz="0.0" iyy="2.3516266e-07" iyz="0.0" izz="2.691504e-07" />
        </inertial>
        <visual>
            <origin rpy="0 0 0" xyz="0 0 0" />
            <geometry>
                <mesh filename="package://qb_hand_description/meshes/ph_short.stl" scale="0.001 0.001 0.001" />
            </geometry>
            <material name="qbhand/middle" />
        </visual>
        <collision>
            <origin rpy="0 0 0" xyz="0 0 0" />
            <geometry>
                <mesh filename="package://qb_hand_description/meshes/ph_short_collision.stl" scale="0.001 0.001 0.001" />
            </geometry>
        </collision>
    </link>
    <gazebo reference="qbhand_index_middle_link">
        <self_collide>1</self_collide>
        <!-- TODO: add other Gazebo Link properties (http://sdformat.org/spec?elem=link) -->
        <!--      <collision>-->
        <!--        <surface>-->
        <!--          <contact>-->
        <!--            <ode>-->
        <!--              <kp>1.0</kp>-->
        <!--              <kd>0.01</kd>-->
        <!--              <max_vel>0.0</max_vel>-->
        <!--              <min_depth>0.001</min_depth>-->
        <!--            </ode>-->
        <!--          </contact>-->
        <!--          <friction>-->
        <!--            <ode>-->
        <!--              <mu>0.9</mu>-->
        <!--              <mu2>0.9</mu2>-->
        <!--            </ode>-->
        <!--          </friction>-->
        <!--        </surface>-->
        <!--      </collision>-->
    </gazebo>
    <joint name="qbhand_index_distal_joint" type="revolute">
        <origin rpy="0 0 0" xyz="0.009 0 0" />
        <parent link="qbhand_index_middle_link" />
        <child link="qbhand_index_distal_virtual_link" />
        <axis xyz="0 0 -1" />
        <dynamics damping="0.0" friction="0.0" />
        <limit effort="100" lower="0.0" upper="0.785" velocity="100" />
        <mimic joint="qbhand_synergy_joint" multiplier="0.785" />
    </joint>
    <transmission name="qbhand_transmission">
        <type>transmission_interface/qbMoveTransmission</type>
        <joint name="qbhand_index_distal_joint">
            <hardwareInterface>hardware_interface/EffortJointInterface</hardwareInterface>
        </joint>
        <actuator name="qbhand_index_distal_joint">
            <hardwareInterface>hardware_interface/EffortJointInterface</hardwareInterface>
        </actuator>
    </transmission>
    <gazebo reference="qbhand_index_distal_joint">
        <!-- TODO: add other Gazebo Joint properties (http://sdformat.org/spec?elem=joint) -->
    </gazebo>
    <link name="qbhand_index_distal_virtual_link">
        <inertial>
            <origin rpy="0 0 0" xyz="0 0 0" />
            <mass value="1e-4" />
            <inertia ixx="1e-9" ixy="0.0" ixz="0.0" iyy="1e-9" iyz="0.0" izz="1e-9" />
        </inertial>
    </link>
    <joint name="qbhand_index_distal_virtual_joint" type="revolute">
        <origin rpy="0 0 0" xyz="0.013 0 0" />
        <parent link="qbhand_index_distal_virtual_link" />
        <child link="qbhand_index_distal_link" />
        <axis xyz="0 0 -1" />
        <dynamics damping="0.0" friction="0.0" />
        <limit effort="100" lower="0.0" upper="0.785" velocity="100" />
        <mimic joint="qbhand_index_distal_joint" multiplier="1.0" />
    </joint>
    <transmission name="qbhand_transmission">
        <type>transmission_interface/qbMoveTransmission</type>
        <joint name="qbhand_index_distal_virtual_joint">
            <hardwareInterface>hardware_interface/EffortJointInterface</hardwareInterface>
        </joint>
        <actuator name="qbhand_index_distal_virtual_joint">
            <hardwareInterface>hardware_interface/EffortJointInterface</hardwareInterface>
        </actuator>
    </transmission>
    <gazebo reference="qbhand_index_distal_virtual_joint">
        <!-- TODO: add other Gazebo Joint properties (http://sdformat.org/spec?elem=joint) -->
    </gazebo>
    <link name="qbhand_index_distal_link">
        <inertial>
            <mass value="0.009" />
            <origin rpy="0 0 0" xyz="8.8025467e-03 -1.7219289e-03 0.0" />
            <inertia ixx="2.6586142e-07" ixy="1.2416847e-08" ixz="0.0" iyy="5.9935767e-07" iyz="0.0" izz="6.6781963e-07" />
        </inertial>
        <visual>
            <origin rpy="0 0 0" xyz="0 0 0" />
            <geometry>
                <mesh filename="package://qb_hand_description/meshes/ph_distal.stl" scale="0.001 0.001 0.001" />
            </geometry>
            <material name="qbhand/distal" />
        </visual>
        <collision>
            <origin rpy="0 0 0" xyz="0 0 0" />
            <geometry>
                <mesh filename="package://qb_hand_description/meshes/ph_distal_collision.stl" scale="0.001 0.001 0.001" />
            </geometry>
        </collision>
    </link>
    <gazebo reference="qbhand_index_distal_link">
        <self_collide>1</self_collide>
        <!-- TODO: add other Gazebo Link properties (http://sdformat.org/spec?elem=link) -->
        <!--      <collision>-->
        <!--        <surface>-->
        <!--          <contact>-->
        <!--            <ode>-->
        <!--              <kp>1.0</kp>-->
        <!--              <kd>0.01</kd>-->
        <!--              <max_vel>0.0</max_vel>-->
        <!--              <min_depth>0.001</min_depth>-->
        <!--            </ode>-->
        <!--          </contact>-->
        <!--          <friction>-->
        <!--            <ode>-->
        <!--              <mu>0.9</mu>-->
        <!--              <mu2>0.9</mu2>-->
        <!--            </ode>-->
        <!--          </friction>-->
        <!--        </surface>-->
        <!--      </collision>-->
    </gazebo>
    <joint name="qbhand_middle_knuckle_joint" type="revolute">
        <origin rpy="0 0 1.57" xyz="0 0 0.014" />
        <parent link="qbhand_palm_link" />
        <child link="qbhand_middle_knuckle_link" />
        <axis xyz="0 0 -1" />
        <dynamics damping="0.0" friction="0.0" />
        <limit effort="100" lower="-0.524" upper="0.524" velocity="100" />
        <mimic joint="qbhand_synergy_joint" multiplier="0.0" />
    </joint>
    <transmission name="qbhand_transmission">
        <type>transmission_interface/qbMoveTransmission</type>
        <joint name="qbhand_middle_knuckle_joint">
            <hardwareInterface>hardware_interface/EffortJointInterface</hardwareInterface>
        </joint>
        <actuator name="qbhand_middle_knuckle_joint">
            <hardwareInterface>hardware_interface/EffortJointInterface</hardwareInterface>
        </actuator>
    </transmission>
    <gazebo reference="qbhand_middle_knuckle_joint">
        <!-- TODO: add other Gazebo Joint properties (http://sdformat.org/spec?elem=joint) -->
    </gazebo>
    <link name="qbhand_middle_knuckle_link">
        <inertial>
            <mass value="0.0095" />
            <origin rpy="0 0 0" xyz="4.2753603e-04  0.0 -1.4321738e-03" />
            <inertia ixx="6.4337303e-07" ixy="0.0" ixz="-3.9373913e-08" iyy="1.1253771e-06" iyz="0.0" izz="7.2336948e-07" />
        </inertial>
        <visual>
            <origin rpy="0 0 0" xyz="0 0 0" />
            <geometry>
                <mesh filename="package://qb_hand_description/meshes/ph_knuckle.stl" scale="0.001 0.001 0.001" />
            </geometry>
            <material name="qbhand/knuckle" />
        </visual>
        <collision>
            <origin rpy="0 0 0" xyz="0 0 0" />
            <geometry>
                <mesh filename="package://qb_hand_description/meshes/ph_knuckle_collision.stl" scale="0.001 0.001 0.001" />
            </geometry>
        </collision>
    </link>
    <gazebo reference="qbhand_middle_knuckle_link">
        <self_collide>1</self_collide>
        <!-- TODO: add other Gazebo Link properties (http://sdformat.org/spec?elem=link) -->
        <!--      <collision>-->
        <!--        <surface>-->
        <!--          <contact>-->
        <!--            <ode>-->
        <!--              <kp>1.0</kp>-->
        <!--              <kd>0.01</kd>-->
        <!--              <max_vel>0.0</max_vel>-->
        <!--              <min_depth>0.001</min_depth>-->
        <!--            </ode>-->
        <!--          </contact>-->
        <!--          <friction>-->
        <!--            <ode>-->
        <!--              <mu>0.9</mu>-->
        <!--              <mu2>0.9</mu2>-->
        <!--            </ode>-->
        <!--          </friction>-->
        <!--        </surface>-->
        <!--      </collision>-->
    </gazebo>
    <joint name="qbhand_middle_proximal_joint" type="revolute">
        <origin rpy="1.57 0 0" xyz="0.009 0 0" />
        <parent link="qbhand_middle_knuckle_link" />
        <child link="qbhand_middle_proximal_virtual_link" />
        <axis xyz="0 0 -1" />
        <dynamics damping="0.0" friction="0.0" />
        <limit effort="100" lower="0.0" upper="0.785" velocity="100" />
        <mimic joint="qbhand_synergy_joint" multiplier="0.785" />
    </joint>
    <transmission name="qbhand_transmission">
        <type>transmission_interface/qbMoveTransmission</type>
        <joint name="qbhand_middle_proximal_joint">
            <hardwareInterface>hardware_interface/EffortJointInterface</hardwareInterface>
        </joint>
        <actuator name="qbhand_middle_proximal_joint">
            <hardwareInterface>hardware_interface/EffortJointInterface</hardwareInterface>
        </actuator>
    </transmission>
    <gazebo reference="qbhand_middle_proximal_joint">
        <!-- TODO: add other Gazebo Joint properties (http://sdformat.org/spec?elem=joint) -->
    </gazebo>
    <link name="qbhand_middle_proximal_virtual_link">
        <inertial>
            <origin rpy="0 0 0" xyz="0 0 0" />
            <mass value="1e-4" />
            <inertia ixx="1e-9" ixy="0.0" ixz="0.0" iyy="1e-9" iyz="0.0" izz="1e-9" />
        </inertial>
    </link>
    <joint name="qbhand_middle_proximal_virtual_joint" type="revolute">
        <origin rpy="0 0 0" xyz="0.013 0 0" />
        <parent link="qbhand_middle_proximal_virtual_link" />
        <child link="qbhand_middle_proximal_link" />
        <axis xyz="0 0 -1" />
        <dynamics damping="0.0" friction="0.0" />
        <limit effort="100" lower="0.0" upper="0.785" velocity="100" />
        <mimic joint="qbhand_middle_proximal_joint" multiplier="1.0" />
    </joint>
    <transmission name="qbhand_transmission">
        <type>transmission_interface/qbMoveTransmission</type>
        <joint name="qbhand_middle_proximal_virtual_joint">
            <hardwareInterface>hardware_interface/EffortJointInterface</hardwareInterface>
        </joint>
        <actuator name="qbhand_middle_proximal_virtual_joint">
            <hardwareInterface>hardware_interface/EffortJointInterface</hardwareInterface>
        </actuator>
    </transmission>
    <gazebo reference="qbhand_middle_proximal_virtual_joint">
        <!-- TODO: add other Gazebo Joint properties (http://sdformat.org/spec?elem=joint) -->
    </gazebo>
    <link name="qbhand_middle_proximal_link">
        <inertial>
            <mass value="0.0082" />
            <origin rpy="0 0 0" xyz="8.7707437e-03 -1.7863138e-03 0.0" />
            <inertia ixx="2.2722068e-07" ixy="1.1586053e-08" ixz="0.0" iyy="5.5947233e-07" iyz="0.0" izz="5.9562195e-07" />
        </inertial>
        <visual>
            <origin rpy="0 0 0" xyz="0 0 0" />
            <geometry>
                <mesh filename="package://qb_hand_description/meshes/ph_medium.stl" scale="0.001 0.001 0.001" />
            </geometry>
            <material name="qbhand/proximal" />
        </visual>
        <collision>
            <origin rpy="0 0 0" xyz="0 0 0" />
            <geometry>
                <mesh filename="package://qb_hand_description/meshes/ph_medium_collision.stl" scale="0.001 0.001 0.001" />
            </geometry>
        </collision>
    </link>
    <gazebo reference="qbhand_middle_proximal_link">
        <self_collide>1</self_collide>
        <!-- TODO: add other Gazebo Link properties (http://sdformat.org/spec?elem=link) -->
        <!--      <collision>-->
        <!--        <surface>-->
        <!--          <contact>-->
        <!--            <ode>-->
        <!--              <kp>1.0</kp>-->
        <!--              <kd>0.01</kd>-->
        <!--              <max_vel>0.0</max_vel>-->
        <!--              <min_depth>0.001</min_depth>-->
        <!--            </ode>-->
        <!--          </contact>-->
        <!--          <friction>-->
        <!--            <ode>-->
        <!--              <mu>0.9</mu>-->
        <!--              <mu2>0.9</mu2>-->
        <!--            </ode>-->
        <!--          </friction>-->
        <!--        </surface>-->
        <!--      </collision>-->
    </gazebo>
    <joint name="qbhand_middle_middle_joint" type="revolute">
        <origin rpy="0 0 0" xyz="0.017 0 0" />
        <parent link="qbhand_middle_proximal_link" />
        <child link="qbhand_middle_middle_virtual_link" />
        <axis xyz="0 0 -1" />
        <dynamics damping="0.0" friction="0.0" />
        <limit effort="100" lower="0.0" upper="0.785" velocity="100" />
        <mimic joint="qbhand_synergy_joint" multiplier="0.785" />
    </joint>
    <transmission name="qbhand_transmission">
        <type>transmission_interface/qbMoveTransmission</type>
        <joint name="qbhand_middle_middle_joint">
            <hardwareInterface>hardware_interface/EffortJointInterface</hardwareInterface>
        </joint>
        <actuator name="qbhand_middle_middle_joint">
            <hardwareInterface>hardware_interface/EffortJointInterface</hardwareInterface>
        </actuator>
    </transmission>
    <gazebo reference="qbhand_middle_middle_joint">
        <!-- TODO: add other Gazebo Joint properties (http://sdformat.org/spec?elem=joint) -->
    </gazebo>
    <link name="qbhand_middle_middle_virtual_link">
        <inertial>
            <origin rpy="0 0 0" xyz="0 0 0" />
            <mass value="1e-4" />
            <inertia ixx="1e-9" ixy="0.0" ixz="0.0" iyy="1e-9" iyz="0.0" izz="1e-9" />
        </inertial>
    </link>
    <joint name="qbhand_middle_middle_virtual_joint" type="revolute">
        <origin rpy="0 0 0" xyz="0.013 0 0" />
        <parent link="qbhand_middle_middle_virtual_link" />
        <child link="qbhand_middle_middle_link" />
        <axis xyz="0 0 -1" />
        <dynamics damping="0.0" friction="0.0" />
        <limit effort="100" lower="0.0" upper="0.785" velocity="100" />
        <mimic joint="qbhand_middle_middle_joint" multiplier="1.0" />
    </joint>
    <transmission name="qbhand_transmission">
        <type>transmission_interface/qbMoveTransmission</type>
        <joint name="qbhand_middle_middle_virtual_joint">
            <hardwareInterface>hardware_interface/EffortJointInterface</hardwareInterface>
        </joint>
        <actuator name="qbhand_middle_middle_virtual_joint">
            <hardwareInterface>hardware_interface/EffortJointInterface</hardwareInterface>
        </actuator>
    </transmission>
    <gazebo reference="qbhand_middle_middle_virtual_joint">
        <!-- TODO: add other Gazebo Joint properties (http://sdformat.org/spec?elem=joint) -->
    </gazebo>
    <link name="qbhand_middle_middle_link">
        <inertial>
            <mass value="0.0063" />
            <origin rpy="0 0 0" xyz="4.7601567e-03 -1.3786947e-03 0.0" />
            <inertia ixx="1.8024201e-07" ixy="5.756798e-09" ixz="0.0" iyy="2.3516266e-07" iyz="0.0" izz="2.691504e-07" />
        </inertial>
        <visual>
            <origin rpy="0 0 0" xyz="0 0 0" />
            <geometry>
                <mesh filename="package://qb_hand_description/meshes/ph_short.stl" scale="0.001 0.001 0.001" />
            </geometry>
            <material name="qbhand/middle" />
        </visual>
        <collision>
            <origin rpy="0 0 0" xyz="0 0 0" />
            <geometry>
                <mesh filename="package://qb_hand_description/meshes/ph_short_collision.stl" scale="0.001 0.001 0.001" />
            </geometry>
        </collision>
    </link>
    <gazebo reference="qbhand_middle_middle_link">
        <self_collide>1</self_collide>
        <!-- TODO: add other Gazebo Link properties (http://sdformat.org/spec?elem=link) -->
        <!--      <collision>-->
        <!--        <surface>-->
        <!--          <contact>-->
        <!--            <ode>-->
        <!--              <kp>1.0</kp>-->
        <!--              <kd>0.01</kd>-->
        <!--              <max_vel>0.0</max_vel>-->
        <!--              <min_depth>0.001</min_depth>-->
        <!--            </ode>-->
        <!--          </contact>-->
        <!--          <friction>-->
        <!--            <ode>-->
        <!--              <mu>0.9</mu>-->
        <!--              <mu2>0.9</mu2>-->
        <!--            </ode>-->
        <!--          </friction>-->
        <!--        </surface>-->
        <!--      </collision>-->
    </gazebo>
    <joint name="qbhand_middle_distal_joint" type="revolute">
        <origin rpy="0 0 0" xyz="0.009 0 0" />
        <parent link="qbhand_middle_middle_link" />
        <child link="qbhand_middle_distal_virtual_link" />
        <axis xyz="0 0 -1" />
        <dynamics damping="0.0" friction="0.0" />
        <limit effort="100" lower="0.0" upper="0.785" velocity="100" />
        <mimic joint="qbhand_synergy_joint" multiplier="0.785" />
    </joint>
    <transmission name="qbhand_transmission">
        <type>transmission_interface/qbMoveTransmission</type>
        <joint name="qbhand_middle_distal_joint">
            <hardwareInterface>hardware_interface/EffortJointInterface</hardwareInterface>
        </joint>
        <actuator name="qbhand_middle_distal_joint">
            <hardwareInterface>hardware_interface/EffortJointInterface</hardwareInterface>
        </actuator>
    </transmission>
    <gazebo reference="qbhand_middle_distal_joint">
        <!-- TODO: add other Gazebo Joint properties (http://sdformat.org/spec?elem=joint) -->
    </gazebo>
    <link name="qbhand_middle_distal_virtual_link">
        <inertial>
            <origin rpy="0 0 0" xyz="0 0 0" />
            <mass value="1e-4" />
            <inertia ixx="1e-9" ixy="0.0" ixz="0.0" iyy="1e-9" iyz="0.0" izz="1e-9" />
        </inertial>
    </link>
    <joint name="qbhand_middle_distal_virtual_joint" type="revolute">
        <origin rpy="0 0 0" xyz="0.013 0 0" />
        <parent link="qbhand_middle_distal_virtual_link" />
        <child link="qbhand_middle_distal_link" />
        <axis xyz="0 0 -1" />
        <dynamics damping="0.0" friction="0.0" />
        <limit effort="100" lower="0.0" upper="0.785" velocity="100" />
        <mimic joint="qbhand_middle_distal_joint" multiplier="1.0" />
    </joint>
    <transmission name="qbhand_transmission">
        <type>transmission_interface/qbMoveTransmission</type>
        <joint name="qbhand_middle_distal_virtual_joint">
            <hardwareInterface>hardware_interface/EffortJointInterface</hardwareInterface>
        </joint>
        <actuator name="qbhand_middle_distal_virtual_joint">
            <hardwareInterface>hardware_interface/EffortJointInterface</hardwareInterface>
        </actuator>
    </transmission>
    <gazebo reference="qbhand_middle_distal_virtual_joint">
        <!-- TODO: add other Gazebo Joint properties (http://sdformat.org/spec?elem=joint) -->
    </gazebo>
    <link name="qbhand_middle_distal_link">
        <inertial>
            <mass value="0.009" />
            <origin rpy="0 0 0" xyz="8.8025467e-03 -1.7219289e-03 0.0" />
            <inertia ixx="2.6586142e-07" ixy="1.2416847e-08" ixz="0.0" iyy="5.9935767e-07" iyz="0.0" izz="6.6781963e-07" />
        </inertial>
        <visual>
            <origin rpy="0 0 0" xyz="0 0 0" />
            <geometry>
                <mesh filename="package://qb_hand_description/meshes/ph_distal.stl" scale="0.001 0.001 0.001" />
            </geometry>
            <material name="qbhand/distal" />
        </visual>
        <collision>
            <origin rpy="0 0 0" xyz="0 0 0" />
            <geometry>
                <mesh filename="package://qb_hand_description/meshes/ph_distal_collision.stl" scale="0.001 0.001 0.001" />
            </geometry>
        </collision>
    </link>
    <gazebo reference="qbhand_middle_distal_link">
        <self_collide>1</self_collide>
        <!-- TODO: add other Gazebo Link properties (http://sdformat.org/spec?elem=link) -->
        <!--      <collision>-->
        <!--        <surface>-->
        <!--          <contact>-->
        <!--            <ode>-->
        <!--              <kp>1.0</kp>-->
        <!--              <kd>0.01</kd>-->
        <!--              <max_vel>0.0</max_vel>-->
        <!--              <min_depth>0.001</min_depth>-->
        <!--            </ode>-->
        <!--          </contact>-->
        <!--          <friction>-->
        <!--            <ode>-->
        <!--              <mu>0.9</mu>-->
        <!--              <mu2>0.9</mu2>-->
        <!--            </ode>-->
        <!--          </friction>-->
        <!--        </surface>-->
        <!--      </collision>-->
    </gazebo>
    <joint name="qbhand_ring_knuckle_joint" type="revolute">
        <origin rpy="0 0 1.57" xyz="0.02 -0.007 0.014" />
        <parent link="qbhand_palm_link" />
        <child link="qbhand_ring_knuckle_link" />
        <axis xyz="0 0 -1" />
        <dynamics damping="0.0" friction="0.0" />
        <limit effort="100" lower="-0.524" upper="0.524" velocity="100" />
        <mimic joint="qbhand_synergy_joint" multiplier="0.2" />
    </joint>
    <transmission name="qbhand_transmission">
        <type>transmission_interface/qbMoveTransmission</type>
        <joint name="qbhand_ring_knuckle_joint">
            <hardwareInterface>hardware_interface/EffortJointInterface</hardwareInterface>
        </joint>
        <actuator name="qbhand_ring_knuckle_joint">
            <hardwareInterface>hardware_interface/EffortJointInterface</hardwareInterface>
        </actuator>
    </transmission>
    <gazebo reference="qbhand_ring_knuckle_joint">
        <!-- TODO: add other Gazebo Joint properties (http://sdformat.org/spec?elem=joint) -->
    </gazebo>
    <link name="qbhand_ring_knuckle_link">
        <inertial>
            <mass value="0.0095" />
            <origin rpy="0 0 0" xyz="4.2753603e-04  0.0 -1.4321738e-03" />
            <inertia ixx="6.4337303e-07" ixy="0.0" ixz="-3.9373913e-08" iyy="1.1253771e-06" iyz="0.0" izz="7.2336948e-07" />
        </inertial>
        <visual>
            <origin rpy="0 0 0" xyz="0 0 0" />
            <geometry>
                <mesh filename="package://qb_hand_description/meshes/ph_knuckle.stl" scale="0.001 0.001 0.001" />
            </geometry>
            <material name="qbhand/knuckle" />
        </visual>
        <collision>
            <origin rpy="0 0 0" xyz="0 0 0" />
            <geometry>
                <mesh filename="package://qb_hand_description/meshes/ph_knuckle_collision.stl" scale="0.001 0.001 0.001" />
            </geometry>
        </collision>
    </link>
    <gazebo reference="qbhand_ring_knuckle_link">
        <self_collide>1</self_collide>
        <!-- TODO: add other Gazebo Link properties (http://sdformat.org/spec?elem=link) -->
        <!--      <collision>-->
        <!--        <surface>-->
        <!--          <contact>-->
        <!--            <ode>-->
        <!--              <kp>1.0</kp>-->
        <!--              <kd>0.01</kd>-->
        <!--              <max_vel>0.0</max_vel>-->
        <!--              <min_depth>0.001</min_depth>-->
        <!--            </ode>-->
        <!--          </contact>-->
        <!--          <friction>-->
        <!--            <ode>-->
        <!--              <mu>0.9</mu>-->
        <!--              <mu2>0.9</mu2>-->
        <!--            </ode>-->
        <!--          </friction>-->
        <!--        </surface>-->
        <!--      </collision>-->
    </gazebo>
    <joint name="qbhand_ring_proximal_joint" type="revolute">
        <origin rpy="1.57 0 0" xyz="0.009 0 0" />
        <parent link="qbhand_ring_knuckle_link" />
        <child link="qbhand_ring_proximal_virtual_link" />
        <axis xyz="0 0 -1" />
        <dynamics damping="0.0" friction="0.0" />
        <limit effort="100" lower="0.0" upper="0.785" velocity="100" />
        <mimic joint="qbhand_synergy_joint" multiplier="0.785" />
    </joint>
    <transmission name="qbhand_transmission">
        <type>transmission_interface/qbMoveTransmission</type>
        <joint name="qbhand_ring_proximal_joint">
            <hardwareInterface>hardware_interface/EffortJointInterface</hardwareInterface>
        </joint>
        <actuator name="qbhand_ring_proximal_joint">
            <hardwareInterface>hardware_interface/EffortJointInterface</hardwareInterface>
        </actuator>
    </transmission>
    <gazebo reference="qbhand_ring_proximal_joint">
        <!-- TODO: add other Gazebo Joint properties (http://sdformat.org/spec?elem=joint) -->
    </gazebo>
    <link name="qbhand_ring_proximal_virtual_link">
        <inertial>
            <origin rpy="0 0 0" xyz="0 0 0" />
            <mass value="1e-4" />
            <inertia ixx="1e-9" ixy="0.0" ixz="0.0" iyy="1e-9" iyz="0.0" izz="1e-9" />
        </inertial>
    </link>
    <joint name="qbhand_ring_proximal_virtual_joint" type="revolute">
        <origin rpy="0 0 0" xyz="0.013 0 0" />
        <parent link="qbhand_ring_proximal_virtual_link" />
        <child link="qbhand_ring_proximal_link" />
        <axis xyz="0 0 -1" />
        <dynamics damping="0.0" friction="0.0" />
        <limit effort="100" lower="0.0" upper="0.785" velocity="100" />
        <mimic joint="qbhand_ring_proximal_joint" multiplier="1.0" />
    </joint>
    <transmission name="qbhand_transmission">
        <type>transmission_interface/qbMoveTransmission</type>
        <joint name="qbhand_ring_proximal_virtual_joint">
            <hardwareInterface>hardware_interface/EffortJointInterface</hardwareInterface>
        </joint>
        <actuator name="qbhand_ring_proximal_virtual_joint">
            <hardwareInterface>hardware_interface/EffortJointInterface</hardwareInterface>
        </actuator>
    </transmission>
    <gazebo reference="qbhand_ring_proximal_virtual_joint">
        <!-- TODO: add other Gazebo Joint properties (http://sdformat.org/spec?elem=joint) -->
    </gazebo>
    <link name="qbhand_ring_proximal_link">
        <inertial>
            <mass value="0.0082" />
            <origin rpy="0 0 0" xyz="8.7707437e-03 -1.7863138e-03 0.0" />
            <inertia ixx="2.2722068e-07" ixy="1.1586053e-08" ixz="0.0" iyy="5.5947233e-07" iyz="0.0" izz="5.9562195e-07" />
        </inertial>
        <visual>
            <origin rpy="0 0 0" xyz="0 0 0" />
            <geometry>
                <mesh filename="package://qb_hand_description/meshes/ph_medium.stl" scale="0.001 0.001 0.001" />
            </geometry>
            <material name="qbhand/proximal" />
        </visual>
        <collision>
            <origin rpy="0 0 0" xyz="0 0 0" />
            <geometry>
                <mesh filename="package://qb_hand_description/meshes/ph_medium_collision.stl" scale="0.001 0.001 0.001" />
            </geometry>
        </collision>
    </link>
    <gazebo reference="qbhand_ring_proximal_link">
        <self_collide>1</self_collide>
        <!-- TODO: add other Gazebo Link properties (http://sdformat.org/spec?elem=link) -->
        <!--      <collision>-->
        <!--        <surface>-->
        <!--          <contact>-->
        <!--            <ode>-->
        <!--              <kp>1.0</kp>-->
        <!--              <kd>0.01</kd>-->
        <!--              <max_vel>0.0</max_vel>-->
        <!--              <min_depth>0.001</min_depth>-->
        <!--            </ode>-->
        <!--          </contact>-->
        <!--          <friction>-->
        <!--            <ode>-->
        <!--              <mu>0.9</mu>-->
        <!--              <mu2>0.9</mu2>-->
        <!--            </ode>-->
        <!--          </friction>-->
        <!--        </surface>-->
        <!--      </collision>-->
    </gazebo>
    <joint name="qbhand_ring_middle_joint" type="revolute">
        <origin rpy="0 0 0" xyz="0.017 0 0" />
        <parent link="qbhand_ring_proximal_link" />
        <child link="qbhand_ring_middle_virtual_link" />
        <axis xyz="0 0 -1" />
        <dynamics damping="0.0" friction="0.0" />
        <limit effort="100" lower="0.0" upper="0.785" velocity="100" />
        <mimic joint="qbhand_synergy_joint" multiplier="0.785" />
    </joint>
    <transmission name="qbhand_transmission">
        <type>transmission_interface/qbMoveTransmission</type>
        <joint name="qbhand_ring_middle_joint">
            <hardwareInterface>hardware_interface/EffortJointInterface</hardwareInterface>
        </joint>
        <actuator name="qbhand_ring_middle_joint">
            <hardwareInterface>hardware_interface/EffortJointInterface</hardwareInterface>
        </actuator>
    </transmission>
    <gazebo reference="qbhand_ring_middle_joint">
        <!-- TODO: add other Gazebo Joint properties (http://sdformat.org/spec?elem=joint) -->
    </gazebo>
    <link name="qbhand_ring_middle_virtual_link">
        <inertial>
            <origin rpy="0 0 0" xyz="0 0 0" />
            <mass value="1e-4" />
            <inertia ixx="1e-9" ixy="0.0" ixz="0.0" iyy="1e-9" iyz="0.0" izz="1e-9" />
        </inertial>
    </link>
    <joint name="qbhand_ring_middle_virtual_joint" type="revolute">
        <origin rpy="0 0 0" xyz="0.013 0 0" />
        <parent link="qbhand_ring_middle_virtual_link" />
        <child link="qbhand_ring_middle_link" />
        <axis xyz="0 0 -1" />
        <dynamics damping="0.0" friction="0.0" />
        <limit effort="100" lower="0.0" upper="0.785" velocity="100" />
        <mimic joint="qbhand_ring_middle_joint" multiplier="1.0" />
    </joint>
    <transmission name="qbhand_transmission">
        <type>transmission_interface/qbMoveTransmission</type>
        <joint name="qbhand_ring_middle_virtual_joint">
            <hardwareInterface>hardware_interface/EffortJointInterface</hardwareInterface>
        </joint>
        <actuator name="qbhand_ring_middle_virtual_joint">
            <hardwareInterface>hardware_interface/EffortJointInterface</hardwareInterface>
        </actuator>
    </transmission>
    <gazebo reference="qbhand_ring_middle_virtual_joint">
        <!-- TODO: add other Gazebo Joint properties (http://sdformat.org/spec?elem=joint) -->
    </gazebo>
    <link name="qbhand_ring_middle_link">
        <inertial>
            <mass value="0.0063" />
            <origin rpy="0 0 0" xyz="4.7601567e-03 -1.3786947e-03 0.0" />
            <inertia ixx="1.8024201e-07" ixy="5.756798e-09" ixz="0.0" iyy="2.3516266e-07" iyz="0.0" izz="2.691504e-07" />
        </inertial>
        <visual>
            <origin rpy="0 0 0" xyz="0 0 0" />
            <geometry>
                <mesh filename="package://qb_hand_description/meshes/ph_short.stl" scale="0.001 0.001 0.001" />
            </geometry>
            <material name="qbhand/middle" />
        </visual>
        <collision>
            <origin rpy="0 0 0" xyz="0 0 0" />
            <geometry>
                <mesh filename="package://qb_hand_description/meshes/ph_short_collision.stl" scale="0.001 0.001 0.001" />
            </geometry>
        </collision>
    </link>
    <gazebo reference="qbhand_ring_middle_link">
        <self_collide>1</self_collide>
        <!-- TODO: add other Gazebo Link properties (http://sdformat.org/spec?elem=link) -->
        <!--      <collision>-->
        <!--        <surface>-->
        <!--          <contact>-->
        <!--            <ode>-->
        <!--              <kp>1.0</kp>-->
        <!--              <kd>0.01</kd>-->
        <!--              <max_vel>0.0</max_vel>-->
        <!--              <min_depth>0.001</min_depth>-->
        <!--            </ode>-->
        <!--          </contact>-->
        <!--          <friction>-->
        <!--            <ode>-->
        <!--              <mu>0.9</mu>-->
        <!--              <mu2>0.9</mu2>-->
        <!--            </ode>-->
        <!--          </friction>-->
        <!--        </surface>-->
        <!--      </collision>-->
    </gazebo>
    <joint name="qbhand_ring_distal_joint" type="revolute">
        <origin rpy="0 0 0" xyz="0.009 0 0" />
        <parent link="qbhand_ring_middle_link" />
        <child link="qbhand_ring_distal_virtual_link" />
        <axis xyz="0 0 -1" />
        <dynamics damping="0.0" friction="0.0" />
        <limit effort="100" lower="0.0" upper="0.785" velocity="100" />
        <mimic joint="qbhand_synergy_joint" multiplier="0.785" />
    </joint>
    <transmission name="qbhand_transmission">
        <type>transmission_interface/qbMoveTransmission</type>
        <joint name="qbhand_ring_distal_joint">
            <hardwareInterface>hardware_interface/EffortJointInterface</hardwareInterface>
        </joint>
        <actuator name="qbhand_ring_distal_joint">
            <hardwareInterface>hardware_interface/EffortJointInterface</hardwareInterface>
        </actuator>
    </transmission>
    <gazebo reference="qbhand_ring_distal_joint">
        <!-- TODO: add other Gazebo Joint properties (http://sdformat.org/spec?elem=joint) -->
    </gazebo>
    <link name="qbhand_ring_distal_virtual_link">
        <inertial>
            <origin rpy="0 0 0" xyz="0 0 0" />
            <mass value="1e-4" />
            <inertia ixx="1e-9" ixy="0.0" ixz="0.0" iyy="1e-9" iyz="0.0" izz="1e-9" />
        </inertial>
    </link>
    <joint name="qbhand_ring_distal_virtual_joint" type="revolute">
        <origin rpy="0 0 0" xyz="0.013 0 0" />
        <parent link="qbhand_ring_distal_virtual_link" />
        <child link="qbhand_ring_distal_link" />
        <axis xyz="0 0 -1" />
        <dynamics damping="0.0" friction="0.0" />
        <limit effort="100" lower="0.0" upper="0.785" velocity="100" />
        <mimic joint="qbhand_ring_distal_joint" multiplier="1.0" />
    </joint>
    <transmission name="qbhand_transmission">
        <type>transmission_interface/qbMoveTransmission</type>
        <joint name="qbhand_ring_distal_virtual_joint">
            <hardwareInterface>hardware_interface/EffortJointInterface</hardwareInterface>
        </joint>
        <actuator name="qbhand_ring_distal_virtual_joint">
            <hardwareInterface>hardware_interface/EffortJointInterface</hardwareInterface>
        </actuator>
    </transmission>
    <gazebo reference="qbhand_ring_distal_virtual_joint">
        <!-- TODO: add other Gazebo Joint properties (http://sdformat.org/spec?elem=joint) -->
    </gazebo>
    <link name="qbhand_ring_distal_link">
        <inertial>
            <mass value="0.009" />
            <origin rpy="0 0 0" xyz="8.8025467e-03 -1.7219289e-03 0.0" />
            <inertia ixx="2.6586142e-07" ixy="1.2416847e-08" ixz="0.0" iyy="5.9935767e-07" iyz="0.0" izz="6.6781963e-07" />
        </inertial>
        <visual>
            <origin rpy="0 0 0" xyz="0 0 0" />
            <geometry>
                <mesh filename="package://qb_hand_description/meshes/ph_distal.stl" scale="0.001 0.001 0.001" />
            </geometry>
            <material name="qbhand/distal" />
        </visual>
        <collision>
            <origin rpy="0 0 0" xyz="0 0 0" />
            <geometry>
                <mesh filename="package://qb_hand_description/meshes/ph_distal_collision.stl" scale="0.001 0.001 0.001" />
            </geometry>
        </collision>
    </link>
    <gazebo reference="qbhand_ring_distal_link">
        <self_collide>1</self_collide>
        <!-- TODO: add other Gazebo Link properties (http://sdformat.org/spec?elem=link) -->
        <!--      <collision>-->
        <!--        <surface>-->
        <!--          <contact>-->
        <!--            <ode>-->
        <!--              <kp>1.0</kp>-->
        <!--              <kd>0.01</kd>-->
        <!--              <max_vel>0.0</max_vel>-->
        <!--              <min_depth>0.001</min_depth>-->
        <!--            </ode>-->
        <!--          </contact>-->
        <!--          <friction>-->
        <!--            <ode>-->
        <!--              <mu>0.9</mu>-->
        <!--              <mu2>0.9</mu2>-->
        <!--            </ode>-->
        <!--          </friction>-->
        <!--        </surface>-->
        <!--      </collision>-->
    </gazebo>
    <joint name="qbhand_little_knuckle_joint" type="revolute">
        <origin rpy="0 0 1.57" xyz="0.04 -0.012 0.014" />
        <parent link="qbhand_palm_link" />
        <child link="qbhand_little_knuckle_link" />
        <axis xyz="0 0 -1" />
        <dynamics damping="0.0" friction="0.0" />
        <limit effort="100" lower="-0.524" upper="0.524" velocity="100" />
        <mimic joint="qbhand_synergy_joint" multiplier="0.4" />
    </joint>
    <transmission name="qbhand_transmission">
        <type>transmission_interface/qbMoveTransmission</type>
        <joint name="qbhand_little_knuckle_joint">
            <hardwareInterface>hardware_interface/EffortJointInterface</hardwareInterface>
        </joint>
        <actuator name="qbhand_little_knuckle_joint">
            <hardwareInterface>hardware_interface/EffortJointInterface</hardwareInterface>
        </actuator>
    </transmission>
    <gazebo reference="qbhand_little_knuckle_joint">
        <!-- TODO: add other Gazebo Joint properties (http://sdformat.org/spec?elem=joint) -->
    </gazebo>
    <link name="qbhand_little_knuckle_link">
        <inertial>
            <mass value="0.0095" />
            <origin rpy="0 0 0" xyz="4.2753603e-04  0.0 -1.4321738e-03" />
            <inertia ixx="6.4337303e-07" ixy="0.0" ixz="-3.9373913e-08" iyy="1.1253771e-06" iyz="0.0" izz="7.2336948e-07" />
        </inertial>
        <visual>
            <origin rpy="0 0 0" xyz="0 0 0" />
            <geometry>
                <mesh filename="package://qb_hand_description/meshes/ph_knuckle.stl" scale="0.001 0.001 0.001" />
            </geometry>
            <material name="qbhand/knuckle" />
        </visual>
        <collision>
            <origin rpy="0 0 0" xyz="0 0 0" />
            <geometry>
                <mesh filename="package://qb_hand_description/meshes/ph_knuckle_collision.stl" scale="0.001 0.001 0.001" />
            </geometry>
        </collision>
    </link>
    <gazebo reference="qbhand_little_knuckle_link">
        <self_collide>1</self_collide>
        <!-- TODO: add other Gazebo Link properties (http://sdformat.org/spec?elem=link) -->
        <!--      <collision>-->
        <!--        <surface>-->
        <!--          <contact>-->
        <!--            <ode>-->
        <!--              <kp>1.0</kp>-->
        <!--              <kd>0.01</kd>-->
        <!--              <max_vel>0.0</max_vel>-->
        <!--              <min_depth>0.001</min_depth>-->
        <!--            </ode>-->
        <!--          </contact>-->
        <!--          <friction>-->
        <!--            <ode>-->
        <!--              <mu>0.9</mu>-->
        <!--              <mu2>0.9</mu2>-->
        <!--            </ode>-->
        <!--          </friction>-->
        <!--        </surface>-->
        <!--      </collision>-->
    </gazebo>
    <joint name="qbhand_little_proximal_joint" type="revolute">
        <origin rpy="1.57 0 0" xyz="0.009 0 0" />
        <parent link="qbhand_little_knuckle_link" />
        <child link="qbhand_little_proximal_virtual_link" />
        <axis xyz="0 0 -1" />
        <dynamics damping="0.0" friction="0.0" />
        <limit effort="100" lower="0.0" upper="0.785" velocity="100" />
        <mimic joint="qbhand_synergy_joint" multiplier="0.785" />
    </joint>
    <transmission name="qbhand_transmission">
        <type>transmission_interface/qbMoveTransmission</type>
        <joint name="qbhand_little_proximal_joint">
            <hardwareInterface>hardware_interface/EffortJointInterface</hardwareInterface>
        </joint>
        <actuator name="qbhand_little_proximal_joint">
            <hardwareInterface>hardware_interface/EffortJointInterface</hardwareInterface>
        </actuator>
    </transmission>
    <gazebo reference="qbhand_little_proximal_joint">
        <!-- TODO: add other Gazebo Joint properties (http://sdformat.org/spec?elem=joint) -->
    </gazebo>
    <link name="qbhand_little_proximal_virtual_link">
        <inertial>
            <origin rpy="0 0 0" xyz="0 0 0" />
            <mass value="1e-4" />
            <inertia ixx="1e-9" ixy="0.0" ixz="0.0" iyy="1e-9" iyz="0.0" izz="1e-9" />
        </inertial>
    </link>
    <joint name="qbhand_little_proximal_virtual_joint" type="revolute">
        <origin rpy="0 0 0" xyz="0.013 0 0" />
        <parent link="qbhand_little_proximal_virtual_link" />
        <child link="qbhand_little_proximal_link" />
        <axis xyz="0 0 -1" />
        <dynamics damping="0.0" friction="0.0" />
        <limit effort="100" lower="0.0" upper="0.785" velocity="100" />
        <mimic joint="qbhand_little_proximal_joint" multiplier="1.0" />
    </joint>
    <transmission name="qbhand_transmission">
        <type>transmission_interface/qbMoveTransmission</type>
        <joint name="qbhand_little_proximal_virtual_joint">
            <hardwareInterface>hardware_interface/EffortJointInterface</hardwareInterface>
        </joint>
        <actuator name="qbhand_little_proximal_virtual_joint">
            <hardwareInterface>hardware_interface/EffortJointInterface</hardwareInterface>
        </actuator>
    </transmission>
    <gazebo reference="qbhand_little_proximal_virtual_joint">
        <!-- TODO: add other Gazebo Joint properties (http://sdformat.org/spec?elem=joint) -->
    </gazebo>
    <link name="qbhand_little_proximal_link">
        <inertial>
            <mass value="0.0063" />
            <origin rpy="0 0 0" xyz="4.7601567e-03 -1.3786947e-03 0.0" />
            <inertia ixx="1.8024201e-07" ixy="5.756798e-09" ixz="0.0" iyy="2.3516266e-07" iyz="0.0" izz="2.691504e-07" />
        </inertial>
        <visual>
            <origin rpy="0 0 0" xyz="0 0 0" />
            <geometry>
                <mesh filename="package://qb_hand_description/meshes/ph_short.stl" scale="0.001 0.001 0.001" />
            </geometry>
            <material name="qbhand/proximal" />
        </visual>
        <collision>
            <origin rpy="0 0 0" xyz="0 0 0" />
            <geometry>
                <mesh filename="package://qb_hand_description/meshes/ph_short_collision.stl" scale="0.001 0.001 0.001" />
            </geometry>
        </collision>
    </link>
    <gazebo reference="qbhand_little_proximal_link">
        <self_collide>1</self_collide>
        <!-- TODO: add other Gazebo Link properties (http://sdformat.org/spec?elem=link) -->
        <!--      <collision>-->
        <!--        <surface>-->
        <!--          <contact>-->
        <!--            <ode>-->
        <!--              <kp>1.0</kp>-->
        <!--              <kd>0.01</kd>-->
        <!--              <max_vel>0.0</max_vel>-->
        <!--              <min_depth>0.001</min_depth>-->
        <!--            </ode>-->
        <!--          </contact>-->
        <!--          <friction>-->
        <!--            <ode>-->
        <!--              <mu>0.9</mu>-->
        <!--              <mu2>0.9</mu2>-->
        <!--            </ode>-->
        <!--          </friction>-->
        <!--        </surface>-->
        <!--      </collision>-->
    </gazebo>
    <joint name="qbhand_little_middle_joint" type="revolute">
        <origin rpy="0 0 0" xyz="0.009 0 0" />
        <parent link="qbhand_little_proximal_link" />
        <child link="qbhand_little_middle_virtual_link" />
        <axis xyz="0 0 -1" />
        <dynamics damping="0.0" friction="0.0" />
        <limit effort="100" lower="0.0" upper="0.785" velocity="100" />
        <mimic joint="qbhand_synergy_joint" multiplier="0.785" />
    </joint>
    <transmission name="qbhand_transmission">
        <type>transmission_interface/qbMoveTransmission</type>
        <joint name="qbhand_little_middle_joint">
            <hardwareInterface>hardware_interface/EffortJointInterface</hardwareInterface>
        </joint>
        <actuator name="qbhand_little_middle_joint">
            <hardwareInterface>hardware_interface/EffortJointInterface</hardwareInterface>
        </actuator>
    </transmission>
    <gazebo reference="qbhand_little_middle_joint">
        <!-- TODO: add other Gazebo Joint properties (http://sdformat.org/spec?elem=joint) -->
    </gazebo>
    <link name="qbhand_little_middle_virtual_link">
        <inertial>
            <origin rpy="0 0 0" xyz="0 0 0" />
            <mass value="1e-4" />
            <inertia ixx="1e-9" ixy="0.0" ixz="0.0" iyy="1e-9" iyz="0.0" izz="1e-9" />
        </inertial>
    </link>
    <joint name="qbhand_little_middle_virtual_joint" type="revolute">
        <origin rpy="0 0 0" xyz="0.013 0 0" />
        <parent link="qbhand_little_middle_virtual_link" />
        <child link="qbhand_little_middle_link" />
        <axis xyz="0 0 -1" />
        <dynamics damping="0.0" friction="0.0" />
        <limit effort="100" lower="0.0" upper="0.785" velocity="100" />
        <mimic joint="qbhand_little_middle_joint" multiplier="1.0" />
    </joint>
    <transmission name="qbhand_transmission">
        <type>transmission_interface/qbMoveTransmission</type>
        <joint name="qbhand_little_middle_virtual_joint">
            <hardwareInterface>hardware_interface/EffortJointInterface</hardwareInterface>
        </joint>
        <actuator name="qbhand_little_middle_virtual_joint">
            <hardwareInterface>hardware_interface/EffortJointInterface</hardwareInterface>
        </actuator>
    </transmission>
    <gazebo reference="qbhand_little_middle_virtual_joint">
        <!-- TODO: add other Gazebo Joint properties (http://sdformat.org/spec?elem=joint) -->
    </gazebo>
    <link name="qbhand_little_middle_link">
        <inertial>
            <mass value="0.0063" />
            <origin rpy="0 0 0" xyz="4.7601567e-03 -1.3786947e-03 0.0" />
            <inertia ixx="1.8024201e-07" ixy="5.756798e-09" ixz="0.0" iyy="2.3516266e-07" iyz="0.0" izz="2.691504e-07" />
        </inertial>
        <visual>
            <origin rpy="0 0 0" xyz="0 0 0" />
            <geometry>
                <mesh filename="package://qb_hand_description/meshes/ph_short.stl" scale="0.001 0.001 0.001" />
            </geometry>
            <material name="qbhand/middle" />
        </visual>
        <collision>
            <origin rpy="0 0 0" xyz="0 0 0" />
            <geometry>
                <mesh filename="package://qb_hand_description/meshes/ph_short_collision.stl" scale="0.001 0.001 0.001" />
            </geometry>
        </collision>
    </link>
    <gazebo reference="qbhand_little_middle_link">
        <self_collide>1</self_collide>
        <!-- TODO: add other Gazebo Link properties (http://sdformat.org/spec?elem=link) -->
        <!--      <collision>-->
        <!--        <surface>-->
        <!--          <contact>-->
        <!--            <ode>-->
        <!--              <kp>1.0</kp>-->
        <!--              <kd>0.01</kd>-->
        <!--              <max_vel>0.0</max_vel>-->
        <!--              <min_depth>0.001</min_depth>-->
        <!--            </ode>-->
        <!--          </contact>-->
        <!--          <friction>-->
        <!--            <ode>-->
        <!--              <mu>0.9</mu>-->
        <!--              <mu2>0.9</mu2>-->
        <!--            </ode>-->
        <!--          </friction>-->
        <!--        </surface>-->
        <!--      </collision>-->
    </gazebo>
    <joint name="qbhand_little_distal_joint" type="revolute">
        <origin rpy="0 0 0" xyz="0.009 0 0" />
        <parent link="qbhand_little_middle_link" />
        <child link="qbhand_little_distal_virtual_link" />
        <axis xyz="0 0 -1" />
        <dynamics damping="0.0" friction="0.0" />
        <limit effort="100" lower="0.0" upper="0.785" velocity="100" />
        <mimic joint="qbhand_synergy_joint" multiplier="0.785" />
    </joint>
    <transmission name="qbhand_transmission">
        <type>transmission_interface/qbMoveTransmission</type>
        <joint name="qbhand_little_distal_joint">
            <hardwareInterface>hardware_interface/EffortJointInterface</hardwareInterface>
        </joint>
        <actuator name="qbhand_little_distal_joint">
            <hardwareInterface>hardware_interface/EffortJointInterface</hardwareInterface>
        </actuator>
    </transmission>
    <gazebo reference="qbhand_little_distal_joint">
        <!-- TODO: add other Gazebo Joint properties (http://sdformat.org/spec?elem=joint) -->
    </gazebo>
    <link name="qbhand_little_distal_virtual_link">
        <inertial>
            <origin rpy="0 0 0" xyz="0 0 0" />
            <mass value="1e-4" />
            <inertia ixx="1e-9" ixy="0.0" ixz="0.0" iyy="1e-9" iyz="0.0" izz="1e-9" />
        </inertial>
    </link>
    <joint name="qbhand_little_distal_virtual_joint" type="revolute">
        <origin rpy="0 0 0" xyz="0.013 0 0" />
        <parent link="qbhand_little_distal_virtual_link" />
        <child link="qbhand_little_distal_link" />
        <axis xyz="0 0 -1" />
        <dynamics damping="0.0" friction="0.0" />
        <limit effort="100" lower="0.0" upper="0.785" velocity="100" />
        <mimic joint="qbhand_little_distal_joint" multiplier="1.0" />
    </joint>
    <transmission name="qbhand_transmission">
        <type>transmission_interface/qbMoveTransmission</type>
        <joint name="qbhand_little_distal_virtual_joint">
            <hardwareInterface>hardware_interface/EffortJointInterface</hardwareInterface>
        </joint>
        <actuator name="qbhand_little_distal_virtual_joint">
            <hardwareInterface>hardware_interface/EffortJointInterface</hardwareInterface>
        </actuator>
    </transmission>
    <gazebo reference="qbhand_little_distal_virtual_joint">
        <!-- TODO: add other Gazebo Joint properties (http://sdformat.org/spec?elem=joint) -->
    </gazebo>
    <link name="qbhand_little_distal_link">
        <inertial>
            <mass value="0.009" />
            <origin rpy="0 0 0" xyz="8.8025467e-03 -1.7219289e-03 0.0" />
            <inertia ixx="2.6586142e-07" ixy="1.2416847e-08" ixz="0.0" iyy="5.9935767e-07" iyz="0.0" izz="6.6781963e-07" />
        </inertial>
        <visual>
            <origin rpy="0 0 0" xyz="0 0 0" />
            <geometry>
                <mesh filename="package://qb_hand_description/meshes/ph_distal.stl" scale="0.001 0.001 0.001" />
            </geometry>
            <material name="qbhand/distal" />
        </visual>
        <collision>
            <origin rpy="0 0 0" xyz="0 0 0" />
            <geometry>
                <mesh filename="package://qb_hand_description/meshes/ph_distal_collision.stl" scale="0.001 0.001 0.001" />
            </geometry>
        </collision>
    </link>
    <gazebo reference="qbhand_little_distal_link">
        <self_collide>1</self_collide>
        <!-- TODO: add other Gazebo Link properties (http://sdformat.org/spec?elem=link) -->
        <!--      <collision>-->
        <!--        <surface>-->
        <!--          <contact>-->
        <!--            <ode>-->
        <!--              <kp>1.0</kp>-->
        <!--              <kd>0.01</kd>-->
        <!--              <max_vel>0.0</max_vel>-->
        <!--              <min_depth>0.001</min_depth>-->
        <!--            </ode>-->
        <!--          </contact>-->
        <!--          <friction>-->
        <!--            <ode>-->
        <!--              <mu>0.9</mu>-->
        <!--              <mu2>0.9</mu2>-->
        <!--            </ode>-->
        <!--          </friction>-->
        <!--        </surface>-->
        <!--      </collision>-->
    </gazebo>
    <joint name="qbhand_end_effector_fixed_joint" type="fixed">
        <origin rpy="-1.57 0 0" xyz="-0.03 0.060 0.142" />
        <parent link="qbhand_base_link" />
        <child link="qbhand_end_effector_link" />
    </joint>
    <link name="qbhand_end_effector_link" />
    <gazebo>
        <plugin filename="libqb_hand_gazebo_plugin.so" name="qb_hand_gazebo_plugin" />
    </gazebo>
    <link name="s1_2">
        <inertial>
            <origin xyz="-0.000550677678532745 -0.0842035718164216 -0.0521489352417439" rpy="0 0 0" />
            <mass value="0.830099234775223" />
            <inertia ixx="0.0032547816918938" ixy="-0.000240096808711407" ixz="9.27582020728764E-05" iyy="0.00341758310179647" iyz="-0.000732394678304823" izz="0.00293879726561974" />
        </inertial>
        <visual>
            <origin xyz="0 0 0" rpy="0 0 0" />
            <geometry>
                <mesh filename="package://air_dual_arm_description/meshes/s1_2.STL" />
            </geometry>
            <material name="">
                <color rgba="0.792156862745098 0.819607843137255 0.933333333333333 1" />
            </material>
        </visual>
        <collision>
            <origin xyz="0 0 0" rpy="0 0 0" />
            <geometry>
                <mesh filename="package://air_dual_arm_description/meshes/s1_2.STL" />
            </geometry>
        </collision>
    </link>
    <joint name="s1_2j" type="revolute">
        <origin xyz="-0.002 0.143 1.1174" rpy="-1.5708 0 3.1416" />
        <parent link="base_link" />
        <child link="s1_2" />
        <axis xyz="0 1 0" />
        <limit lower="0" upper="1.5708" effort="0" velocity="0" />
    </joint>
    <link name="s2_2">
        <inertial>
            <origin xyz="-0.0166461904252623 -0.0527606118737116 0.0424999999999992" rpy="0 0 0" />
            <mass value="0.101764872719582" />
            <inertia ixx="0.000166278611392907" ixy="3.48973165757439E-07" ixz="-1.20253986935948E-10" iyy="5.52814894228262E-05" iyz="-1.31951186249406E-18" izz="0.00017880842306185" />
        </inertial>
        <visual>
            <origin xyz="0 0 0" rpy="0 0 0" />
            <geometry>
                <mesh filename="package://air_dual_arm_description/meshes/s2_2.STL" />
            </geometry>
            <material name="">
                <color rgba="0.792156862745098 0.819607843137255 0.933333333333333 1" />
            </material>
        </visual>
        <collision>
            <origin xyz="0 0 0" rpy="0 0 0" />
            <geometry>
                <mesh filename="package://air_dual_arm_description/meshes/s2_2.STL" />
            </geometry>
        </collision>
    </link>
    <joint name="s2_2j" type="revolute">
        <origin xyz="-0.1115 -0.12929 -0.131" rpy="0 0 -3.1416" />
        <parent link="s1_2" />
        <child link="s2_2" />
        <axis xyz="0 0 1" />
        <limit lower="-1" upper="1" effort="0" velocity="0" />
    </joint>
    <link name="s3_2">
        <inertial>
            <origin xyz="0.025078182994546 0.107522775667075 -0.00425054953884735" rpy="0 0 0" />
            <mass value="0.562432726876805" />
            <inertia ixx="0.00250441787722491" ixy="-2.9488181318966E-05" ixz="1.14283315631225E-06" iyy="0.00027561889842084" iyz="-4.01105669617396E-05" izz="0.00242878623308718" />
        </inertial>
        <visual>
            <origin xyz="0 0 0" rpy="0 0 0" />
            <geometry>
                <mesh filename="package://air_dual_arm_description/meshes/s3_2.STL" />
            </geometry>
            <material name="">
                <color rgba="0.792156862745098 0.819607843137255 0.933333333333333 1" />
            </material>
        </visual>
        <collision>
            <origin xyz="0 0 0" rpy="0 0 0" />
            <geometry>
                <mesh filename="package://air_dual_arm_description/meshes/s3_2.STL" />
            </geometry>
        </collision>
    </link>
    <joint name="s3_2j" type="revolute">
        <origin xyz="0.0025 -0.1023 0.0425" rpy="0 0 3.1416" />
        <parent link="s2_2" />
        <child link="s3_2" />
        <axis xyz="0 1 0" />
        <limit lower="-1" upper="1" effort="0" velocity="0" />
    </joint>
    <link name="e_2">
        <inertial>
            <origin xyz="-0.131131630239151 0.0102994228298454 -0.00468829588895486" rpy="0 0 0" />
            <mass value="0.46148926731283" />
            <inertia ixx="0.000222005498543674" ixy="-2.13012558823749E-05" ixz="7.48982457141488E-06" iyy="0.00177579570891962" iyz="4.1085838810028E-05" izz="0.00177847625873136" />
        </inertial>
        <visual>
            <origin xyz="0 0 0" rpy="0 0 0" />
            <geometry>
                <mesh filename="package://air_dual_arm_description/meshes/e_2.STL" />
            </geometry>
            <material name="">
                <color rgba="0.792156862745098 0.819607843137255 0.933333333333333 1" />
            </material>
        </visual>
        <collision>
            <origin xyz="0 0 0" rpy="0 0 0" />
            <geometry>
                <mesh filename="package://air_dual_arm_description/meshes/e_2.STL" />
            </geometry>
        </collision>
    </link>
    <joint name="e_2j" type="revolute">
        <origin xyz="0.005 0.2837 0" rpy="0 0 0" />
        <parent link="s3_2" />
        <child link="e_2" />
        <axis xyz="0 0 1" />
        <limit lower="-1.5708" upper="1.5708" effort="0" velocity="0" />
    </joint>
    <link name="roll_2">
        <inertial>
            <origin xyz="-7.67800267809093E-11 -5.0940585083481E-10 9.34686772424698E-11" rpy="0 0 0" />
            <mass value="0.0122903153007481" />
            <inertia ixx="2.99852270531829E-06" ixy="-6.85310892693233E-14" ixz="4.77163554421916E-15" iyy="2.9985196485054E-06" iyz="-1.26143577302615E-13" izz="5.70407489396405E-06" />
        </inertial>
        <visual>
            <origin xyz="0 0 0" rpy="0 0 0" />
            <geometry>
                <mesh filename="package://air_dual_arm_description/meshes/roll_2.STL" />
            </geometry>
            <material name="">
                <color rgba="0.898039215686275 0.917647058823529 0.929411764705882 1" />
            </material>
        </visual>
        <collision>
            <origin xyz="0 0 0" rpy="0 0 0" />
            <geometry>
                <mesh filename="package://air_dual_arm_description/meshes/roll_2.STL" />
            </geometry>
        </collision>
    </link>
    <joint name="roll_2j" type="revolute">
        <origin xyz="-0.2625 0 0" rpy="-1.5708 0.7854 1.5708" />
        <parent link="e_2" />
        <child link="roll_2" />
        <axis xyz="1 0 0" />
        <limit lower="-0.34907" upper="0.34907" effort="0" velocity="0" />
    </joint>
    <link name="pitch_2">
        <inertial>
            <origin xyz="0.00272705479614532 0.00272699044805402 0.0248409919985194" rpy="0 0 0" />
            <mass value="0.041110784814742" />
            <inertia ixx="2.99980626219617E-05" ixy="3.5879416169128E-06" ixz="1.12439529077205E-06" iyy="2.99981644750521E-05" iyz="1.12436594478041E-06" izz="4.86107826042292E-05" />
        </inertial>
        <visual>
            <origin xyz="0 0 0" rpy="0 0 0" />
            <geometry>
                <mesh filename="package://air_dual_arm_description/meshes/pitch_2.STL" />
            </geometry>
            <material name="">
                <color rgba="0.792156862745098 0.819607843137255 0.933333333333333 1" />
            </material>
        </visual>
        <collision>
            <origin xyz="0 0 0" rpy="0 0 0" />
            <geometry>
                <mesh filename="package://air_dual_arm_description/meshes/pitch_2.STL" />
            </geometry>
        </collision>
    </link>
    <joint name="pitch_2j" type="revolute">
        <origin xyz="0 0 0" rpy="0 0 -0.7854" />
        <parent link="roll_2" />
        <child link="pitch_2" />
        <axis xyz="0.70711 -0.70711 0" />
        <limit lower="-0.43633" upper="0.43633" effort="0" velocity="0" />
    </joint>
    <!-- <link
    name="yaw_2">
    <inertial>
      <origin
        xyz="-0.108274828509963 0.00881634390948693 0.00587763329446767"
        rpy="0 0 0" />
      <mass
        value="0.131144702182196" />
      <inertia
        ixx="4.12011674037864E-05"
        ixy="-3.95261459421665E-07"
        ixz="-7.09536214834622E-07"
        iyy="2.28647145682731E-05"
        iyz="2.99289504924483E-08"
        izz="2.90711599028872E-05" />
    </inertial>
    <visual>
      <origin
        xyz="0 0 0"
        rpy="0 0 0" />
      <geometry>
        <mesh
          filename="package://air_dual_arm_description/meshes/yaw_2.STL" />
      </geometry>
      <material
        name="">
        <color
          rgba="0.792156862745098 0.819607843137255 0.933333333333333 1" />
      </material>
    </visual>
    <collision>
      <origin
        xyz="0 0 0"
        rpy="0 0 0" />
      <geometry>
        <mesh
          filename="package://air_dual_arm_description/meshes/yaw_2.STL" />
      </geometry>
    </collision>
  </link> -->
    <!--joint
    name="yaw_2j"
    type="revolute">
    <origin
      xyz="0 0 0.020471"
      rpy="0.7854 1.5059 0.7854" />
    <parent
      link="pitch_2" />
    <child
      link="yaw_2" />
    <axis
      xyz="0.9979 -0.045838 -0.045838" />
    <limit
      lower="-0.7854"
      upper="5.4978"
      effort="0"
      velocity="0" />
  </joint-->
    <!-- End-effector -->
    <!--link name="tool0"/>
  <joint name="end_effector_frame_fixed_joint" type="fixed">
    <parent link="qbhand_base_link"/>
    <child link="tool0"/>
    <origin xyz="0 0 0.12" rpy="0 0 0"/>
  </joint-->
    <transmission name="trans_s1j">
        <type>transmission_interface/SimpleTransmission</type>
        <joint name="s1j">
            <hardwareInterface>hardware_interface/EffortJointInterface</hardwareInterface>
        </joint>
        <actuator name="s1j_motor">
            <hardwareInterface>hardware_interface/EffortJointInterface</hardwareInterface>
            <mechanicalReduction>1</mechanicalReduction>
        </actuator>
    </transmission>
    <transmission name="trans_s2j">
        <type>transmission_interface/SimpleTransmission</type>
        <joint name="s2j">
            <hardwareInterface>hardware_interface/EffortJointInterface</hardwareInterface>
        </joint>
        <actuator name="s2j_motor">
            <hardwareInterface>hardware_interface/EffortJointInterface</hardwareInterface>
            <mechanicalReduction>1</mechanicalReduction>
        </actuator>
    </transmission>
    <transmission name="trans_s3j">
        <type>transmission_interface/SimpleTransmission</type>
        <joint name="s3j">
            <hardwareInterface>hardware_interface/EffortJointInterface</hardwareInterface>
        </joint>
        <actuator name="s3j_motor">
            <hardwareInterface>hardware_interface/EffortJointInterface</hardwareInterface>
            <mechanicalReduction>1</mechanicalReduction>
        </actuator>
    </transmission>
    <transmission name="trans_ej">
        <type>transmission_interface/SimpleTransmission</type>
        <joint name="ej">
            <hardwareInterface>hardware_interface/EffortJointInterface</hardwareInterface>
        </joint>
        <actuator name="ej_motor">
            <hardwareInterface>hardware_interface/EffortJointInterface</hardwareInterface>
            <mechanicalReduction>1</mechanicalReduction>
        </actuator>
    </transmission>
    <transmission name="trans_rollj">
        <type>transmission_interface/SimpleTransmission</type>
        <joint name="rollj">
            <hardwareInterface>hardware_interface/EffortJointInterface</hardwareInterface>
        </joint>
        <actuator name="rollj_motor">
            <hardwareInterface>hardware_interface/EffortJointInterface</hardwareInterface>
            <mechanicalReduction>1</mechanicalReduction>
        </actuator>
    </transmission>
    <transmission name="trans_pitchj">
        <type>transmission_interface/SimpleTransmission</type>
        <joint name="pitchj">
            <hardwareInterface>hardware_interface/EffortJointInterface</hardwareInterface>
        </joint>
        <actuator name="pitchj_motor">
            <hardwareInterface>hardware_interface/EffortJointInterface</hardwareInterface>
            <mechanicalReduction>1</mechanicalReduction>
        </actuator>
    </transmission>
    <transmission name="trans_yawj">
        <type>transmission_interface/SimpleTransmission</type>
        <joint name="yawj">
            <hardwareInterface>hardware_interface/EffortJointInterface</hardwareInterface>
        </joint>
        <actuator name="yawj_motor">
            <hardwareInterface>hardware_interface/EffortJointInterface</hardwareInterface>
            <mechanicalReduction>1</mechanicalReduction>
        </actuator>
    </transmission>
    <transmission name="trans_qbhand_synergy_joint">
        <type>transmission_interface/SimpleTransmission</type>
        <joint name="qbhand_synergy_joint">
            <hardwareInterface>hardware_interface/EffortJointInterface</hardwareInterface>
        </joint>
        <actuator name="qbhand_synergy_joint_motor">
            <hardwareInterface>hardware_interface/EffortJointInterface</hardwareInterface>
            <mechanicalReduction>1</mechanicalReduction>
        </actuator>
    </transmission>
    <transmission name="trans_qbhand_thumb_knuckle_joint">
        <type>transmission_interface/SimpleTransmission</type>
        <joint name="qbhand_thumb_knuckle_joint">
            <hardwareInterface>hardware_interface/EffortJointInterface</hardwareInterface>
        </joint>
        <actuator name="qbhand_thumb_knuckle_joint_motor">
            <hardwareInterface>hardware_interface/EffortJointInterface</hardwareInterface>
            <mechanicalReduction>1</mechanicalReduction>
        </actuator>
    </transmission>
    <transmission name="trans_qbhand_thumb_proximal_joint">
        <type>transmission_interface/SimpleTransmission</type>
        <joint name="qbhand_thumb_proximal_joint">
            <hardwareInterface>hardware_interface/EffortJointInterface</hardwareInterface>
        </joint>
        <actuator name="qbhand_thumb_proximal_joint_motor">
            <hardwareInterface>hardware_interface/EffortJointInterface</hardwareInterface>
            <mechanicalReduction>1</mechanicalReduction>
        </actuator>
    </transmission>
    <transmission name="trans_qbhand_thumb_proximal_virtual_joint">
        <type>transmission_interface/SimpleTransmission</type>
        <joint name="qbhand_thumb_proximal_virtual_joint">
            <hardwareInterface>hardware_interface/EffortJointInterface</hardwareInterface>
        </joint>
        <actuator name="qbhand_thumb_proximal_virtual_joint_motor">
            <hardwareInterface>hardware_interface/EffortJointInterface</hardwareInterface>
            <mechanicalReduction>1</mechanicalReduction>
        </actuator>
    </transmission>
    <transmission name="trans_qbhand_thumb_distal_joint">
        <type>transmission_interface/SimpleTransmission</type>
        <joint name="qbhand_thumb_distal_joint">
            <hardwareInterface>hardware_interface/EffortJointInterface</hardwareInterface>
        </joint>
        <actuator name="qbhand_thumb_distal_joint_motor">
            <hardwareInterface>hardware_interface/EffortJointInterface</hardwareInterface>
            <mechanicalReduction>1</mechanicalReduction>
        </actuator>
    </transmission>
    <transmission name="trans_qbhand_thumb_distal_virtual_joint">
        <type>transmission_interface/SimpleTransmission</type>
        <joint name="qbhand_thumb_distal_virtual_joint">
            <hardwareInterface>hardware_interface/EffortJointInterface</hardwareInterface>
        </joint>
        <actuator name="qbhand_thumb_distal_virtual_joint_motor">
            <hardwareInterface>hardware_interface/EffortJointInterface</hardwareInterface>
            <mechanicalReduction>1</mechanicalReduction>
        </actuator>
    </transmission>
    <transmission name="trans_qbhand_index_knuckle_joint">
        <type>transmission_interface/SimpleTransmission</type>
        <joint name="qbhand_index_knuckle_joint">
            <hardwareInterface>hardware_interface/EffortJointInterface</hardwareInterface>
        </joint>
        <actuator name="qbhand_index_knuckle_joint_motor">
            <hardwareInterface>hardware_interface/EffortJointInterface</hardwareInterface>
            <mechanicalReduction>1</mechanicalReduction>
        </actuator>
    </transmission>
    <transmission name="trans_qbhand_index_proximal_joint">
        <type>transmission_interface/SimpleTransmission</type>
        <joint name="qbhand_index_proximal_joint">
            <hardwareInterface>hardware_interface/EffortJointInterface</hardwareInterface>
        </joint>
        <actuator name="qbhand_index_proximal_joint_motor">
            <hardwareInterface>hardware_interface/EffortJointInterface</hardwareInterface>
            <mechanicalReduction>1</mechanicalReduction>
        </actuator>
    </transmission>
    <transmission name="trans_qbhand_index_proximal_virtual_joint">
        <type>transmission_interface/SimpleTransmission</type>
        <joint name="qbhand_index_proximal_virtual_joint">
            <hardwareInterface>hardware_interface/EffortJointInterface</hardwareInterface>
        </joint>
        <actuator name="qbhand_index_proximal_virtual_joint_motor">
            <hardwareInterface>hardware_interface/EffortJointInterface</hardwareInterface>
            <mechanicalReduction>1</mechanicalReduction>
        </actuator>
    </transmission>
    <transmission name="trans_qbhand_index_middle_joint">
        <type>transmission_interface/SimpleTransmission</type>
        <joint name="qbhand_index_middle_joint">
            <hardwareInterface>hardware_interface/EffortJointInterface</hardwareInterface>
        </joint>
        <actuator name="qbhand_index_middle_joint_motor">
            <hardwareInterface>hardware_interface/EffortJointInterface</hardwareInterface>
            <mechanicalReduction>1</mechanicalReduction>
        </actuator>
    </transmission>
    <transmission name="trans_qbhand_index_middle_virtual_joint">
        <type>transmission_interface/SimpleTransmission</type>
        <joint name="qbhand_index_middle_virtual_joint">
            <hardwareInterface>hardware_interface/EffortJointInterface</hardwareInterface>
        </joint>
        <actuator name="qbhand_index_middle_virtual_joint_motor">
            <hardwareInterface>hardware_interface/EffortJointInterface</hardwareInterface>
            <mechanicalReduction>1</mechanicalReduction>
        </actuator>
    </transmission>
    <transmission name="trans_qbhand_index_distal_joint">
        <type>transmission_interface/SimpleTransmission</type>
        <joint name="qbhand_index_distal_joint">
            <hardwareInterface>hardware_interface/EffortJointInterface</hardwareInterface>
        </joint>
        <actuator name="qbhand_index_distal_joint_motor">
            <hardwareInterface>hardware_interface/EffortJointInterface</hardwareInterface>
            <mechanicalReduction>1</mechanicalReduction>
        </actuator>
    </transmission>
    <transmission name="trans_qbhand_index_distal_virtual_joint">
        <type>transmission_interface/SimpleTransmission</type>
        <joint name="qbhand_index_distal_virtual_joint">
            <hardwareInterface>hardware_interface/EffortJointInterface</hardwareInterface>
        </joint>
        <actuator name="qbhand_index_distal_virtual_joint_motor">
            <hardwareInterface>hardware_interface/EffortJointInterface</hardwareInterface>
            <mechanicalReduction>1</mechanicalReduction>
        </actuator>
    </transmission>
    <transmission name="trans_qbhand_middle_knuckle_joint">
        <type>transmission_interface/SimpleTransmission</type>
        <joint name="qbhand_middle_knuckle_joint">
            <hardwareInterface>hardware_interface/EffortJointInterface</hardwareInterface>
        </joint>
        <actuator name="qbhand_middle_knuckle_joint_motor">
            <hardwareInterface>hardware_interface/EffortJointInterface</hardwareInterface>
            <mechanicalReduction>1</mechanicalReduction>
        </actuator>
    </transmission>
    <transmission name="trans_qbhand_middle_proximal_joint">
        <type>transmission_interface/SimpleTransmission</type>
        <joint name="qbhand_middle_proximal_joint">
            <hardwareInterface>hardware_interface/EffortJointInterface</hardwareInterface>
        </joint>
        <actuator name="qbhand_middle_proximal_joint_motor">
            <hardwareInterface>hardware_interface/EffortJointInterface</hardwareInterface>
            <mechanicalReduction>1</mechanicalReduction>
        </actuator>
    </transmission>
    <transmission name="trans_qbhand_middle_proximal_virtual_joint">
        <type>transmission_interface/SimpleTransmission</type>
        <joint name="qbhand_middle_proximal_virtual_joint">
            <hardwareInterface>hardware_interface/EffortJointInterface</hardwareInterface>
        </joint>
        <actuator name="qbhand_middle_proximal_virtual_joint_motor">
            <hardwareInterface>hardware_interface/EffortJointInterface</hardwareInterface>
            <mechanicalReduction>1</mechanicalReduction>
        </actuator>
    </transmission>
    <transmission name="trans_qbhand_middle_middle_joint">
        <type>transmission_interface/SimpleTransmission</type>
        <joint name="qbhand_middle_middle_joint">
            <hardwareInterface>hardware_interface/EffortJointInterface</hardwareInterface>
        </joint>
        <actuator name="qbhand_middle_middle_joint_motor">
            <hardwareInterface>hardware_interface/EffortJointInterface</hardwareInterface>
            <mechanicalReduction>1</mechanicalReduction>
        </actuator>
    </transmission>
    <transmission name="trans_qbhand_middle_middle_virtual_joint">
        <type>transmission_interface/SimpleTransmission</type>
        <joint name="qbhand_middle_middle_virtual_joint">
            <hardwareInterface>hardware_interface/EffortJointInterface</hardwareInterface>
        </joint>
        <actuator name="qbhand_middle_middle_virtual_joint_motor">
            <hardwareInterface>hardware_interface/EffortJointInterface</hardwareInterface>
            <mechanicalReduction>1</mechanicalReduction>
        </actuator>
    </transmission>
    <transmission name="trans_qbhand_middle_distal_joint">
        <type>transmission_interface/SimpleTransmission</type>
        <joint name="qbhand_middle_distal_joint">
            <hardwareInterface>hardware_interface/EffortJointInterface</hardwareInterface>
        </joint>
        <actuator name="qbhand_middle_distal_joint_motor">
            <hardwareInterface>hardware_interface/EffortJointInterface</hardwareInterface>
            <mechanicalReduction>1</mechanicalReduction>
        </actuator>
    </transmission>
    <transmission name="trans_qbhand_middle_distal_virtual_joint">
        <type>transmission_interface/SimpleTransmission</type>
        <joint name="qbhand_middle_distal_virtual_joint">
            <hardwareInterface>hardware_interface/EffortJointInterface</hardwareInterface>
        </joint>
        <actuator name="qbhand_middle_distal_virtual_joint_motor">
            <hardwareInterface>hardware_interface/EffortJointInterface</hardwareInterface>
            <mechanicalReduction>1</mechanicalReduction>
        </actuator>
    </transmission>
    <transmission name="trans_qbhand_ring_knuckle_joint">
        <type>transmission_interface/SimpleTransmission</type>
        <joint name="qbhand_ring_knuckle_joint">
            <hardwareInterface>hardware_interface/EffortJointInterface</hardwareInterface>
        </joint>
        <actuator name="qbhand_ring_knuckle_joint_motor">
            <hardwareInterface>hardware_interface/EffortJointInterface</hardwareInterface>
            <mechanicalReduction>1</mechanicalReduction>
        </actuator>
    </transmission>
    <transmission name="trans_qbhand_ring_proximal_joint">
        <type>transmission_interface/SimpleTransmission</type>
        <joint name="qbhand_ring_proximal_joint">
            <hardwareInterface>hardware_interface/EffortJointInterface</hardwareInterface>
        </joint>
        <actuator name="qbhand_ring_proximal_joint_motor">
            <hardwareInterface>hardware_interface/EffortJointInterface</hardwareInterface>
            <mechanicalReduction>1</mechanicalReduction>
        </actuator>
    </transmission>
    <transmission name="trans_qbhand_ring_proximal_virtual_joint">
        <type>transmission_interface/SimpleTransmission</type>
        <joint name="qbhand_ring_proximal_virtual_joint">
            <hardwareInterface>hardware_interface/EffortJointInterface</hardwareInterface>
        </joint>
        <actuator name="qbhand_ring_proximal_virtual_joint_motor">
            <hardwareInterface>hardware_interface/EffortJointInterface</hardwareInterface>
            <mechanicalReduction>1</mechanicalReduction>
        </actuator>
    </transmission>
    <transmission name="trans_qbhand_ring_middle_joint">
        <type>transmission_interface/SimpleTransmission</type>
        <joint name="qbhand_ring_middle_joint">
            <hardwareInterface>hardware_interface/EffortJointInterface</hardwareInterface>
        </joint>
        <actuator name="qbhand_ring_middle_joint_motor">
            <hardwareInterface>hardware_interface/EffortJointInterface</hardwareInterface>
            <mechanicalReduction>1</mechanicalReduction>
        </actuator>
    </transmission>
    <transmission name="trans_qbhand_ring_middle_virtual_joint">
        <type>transmission_interface/SimpleTransmission</type>
        <joint name="qbhand_ring_middle_virtual_joint">
            <hardwareInterface>hardware_interface/EffortJointInterface</hardwareInterface>
        </joint>
        <actuator name="qbhand_ring_middle_virtual_joint_motor">
            <hardwareInterface>hardware_interface/EffortJointInterface</hardwareInterface>
            <mechanicalReduction>1</mechanicalReduction>
        </actuator>
    </transmission>
    <transmission name="trans_qbhand_ring_distal_joint">
        <type>transmission_interface/SimpleTransmission</type>
        <joint name="qbhand_ring_distal_joint">
            <hardwareInterface>hardware_interface/EffortJointInterface</hardwareInterface>
        </joint>
        <actuator name="qbhand_ring_distal_joint_motor">
            <hardwareInterface>hardware_interface/EffortJointInterface</hardwareInterface>
            <mechanicalReduction>1</mechanicalReduction>
        </actuator>
    </transmission>
    <transmission name="trans_qbhand_ring_distal_virtual_joint">
        <type>transmission_interface/SimpleTransmission</type>
        <joint name="qbhand_ring_distal_virtual_joint">
            <hardwareInterface>hardware_interface/EffortJointInterface</hardwareInterface>
        </joint>
        <actuator name="qbhand_ring_distal_virtual_joint_motor">
            <hardwareInterface>hardware_interface/EffortJointInterface</hardwareInterface>
            <mechanicalReduction>1</mechanicalReduction>
        </actuator>
    </transmission>
    <transmission name="trans_qbhand_little_knuckle_joint">
        <type>transmission_interface/SimpleTransmission</type>
        <joint name="qbhand_little_knuckle_joint">
            <hardwareInterface>hardware_interface/EffortJointInterface</hardwareInterface>
        </joint>
        <actuator name="qbhand_little_knuckle_joint_motor">
            <hardwareInterface>hardware_interface/EffortJointInterface</hardwareInterface>
            <mechanicalReduction>1</mechanicalReduction>
        </actuator>
    </transmission>
    <transmission name="trans_qbhand_little_proximal_joint">
        <type>transmission_interface/SimpleTransmission</type>
        <joint name="qbhand_little_proximal_joint">
            <hardwareInterface>hardware_interface/EffortJointInterface</hardwareInterface>
        </joint>
        <actuator name="qbhand_little_proximal_joint_motor">
            <hardwareInterface>hardware_interface/EffortJointInterface</hardwareInterface>
            <mechanicalReduction>1</mechanicalReduction>
        </actuator>
    </transmission>
    <transmission name="trans_qbhand_little_proximal_virtual_joint">
        <type>transmission_interface/SimpleTransmission</type>
        <joint name="qbhand_little_proximal_virtual_joint">
            <hardwareInterface>hardware_interface/EffortJointInterface</hardwareInterface>
        </joint>
        <actuator name="qbhand_little_proximal_virtual_joint_motor">
            <hardwareInterface>hardware_interface/EffortJointInterface</hardwareInterface>
            <mechanicalReduction>1</mechanicalReduction>
        </actuator>
    </transmission>
    <transmission name="trans_qbhand_little_middle_joint">
        <type>transmission_interface/SimpleTransmission</type>
        <joint name="qbhand_little_middle_joint">
            <hardwareInterface>hardware_interface/EffortJointInterface</hardwareInterface>
        </joint>
        <actuator name="qbhand_little_middle_joint_motor">
            <hardwareInterface>hardware_interface/EffortJointInterface</hardwareInterface>
            <mechanicalReduction>1</mechanicalReduction>
        </actuator>
    </transmission>
    <transmission name="trans_qbhand_little_middle_virtual_joint">
        <type>transmission_interface/SimpleTransmission</type>
        <joint name="qbhand_little_middle_virtual_joint">
            <hardwareInterface>hardware_interface/EffortJointInterface</hardwareInterface>
        </joint>
        <actuator name="qbhand_little_middle_virtual_joint_motor">
            <hardwareInterface>hardware_interface/EffortJointInterface</hardwareInterface>
            <mechanicalReduction>1</mechanicalReduction>
        </actuator>
    </transmission>
    <transmission name="trans_qbhand_little_distal_joint">
        <type>transmission_interface/SimpleTransmission</type>
        <joint name="qbhand_little_distal_joint">
            <hardwareInterface>hardware_interface/EffortJointInterface</hardwareInterface>
        </joint>
        <actuator name="qbhand_little_distal_joint_motor">
            <hardwareInterface>hardware_interface/EffortJointInterface</hardwareInterface>
            <mechanicalReduction>1</mechanicalReduction>
        </actuator>
    </transmission>
    <transmission name="trans_qbhand_little_distal_virtual_joint">
        <type>transmission_interface/SimpleTransmission</type>
        <joint name="qbhand_little_distal_virtual_joint">
            <hardwareInterface>hardware_interface/EffortJointInterface</hardwareInterface>
        </joint>
        <actuator name="qbhand_little_distal_virtual_joint_motor">
            <hardwareInterface>hardware_interface/EffortJointInterface</hardwareInterface>
            <mechanicalReduction>1</mechanicalReduction>
        </actuator>
    </transmission>
    <transmission name="trans_s1_2j">
        <type>transmission_interface/SimpleTransmission</type>
        <joint name="s1_2j">
            <hardwareInterface>hardware_interface/EffortJointInterface</hardwareInterface>
        </joint>
        <actuator name="s1_2j_motor">
            <hardwareInterface>hardware_interface/EffortJointInterface</hardwareInterface>
            <mechanicalReduction>1</mechanicalReduction>
        </actuator>
    </transmission>
    <transmission name="trans_s2_2j">
        <type>transmission_interface/SimpleTransmission</type>
        <joint name="s2_2j">
            <hardwareInterface>hardware_interface/EffortJointInterface</hardwareInterface>
        </joint>
        <actuator name="s2_2j_motor">
            <hardwareInterface>hardware_interface/EffortJointInterface</hardwareInterface>
            <mechanicalReduction>1</mechanicalReduction>
        </actuator>
    </transmission>
    <transmission name="trans_s3_2j">
        <type>transmission_interface/SimpleTransmission</type>
        <joint name="s3_2j">
            <hardwareInterface>hardware_interface/EffortJointInterface</hardwareInterface>
        </joint>
        <actuator name="s3_2j_motor">
            <hardwareInterface>hardware_interface/EffortJointInterface</hardwareInterface>
            <mechanicalReduction>1</mechanicalReduction>
        </actuator>
    </transmission>
    <transmission name="trans_e_2j">
        <type>transmission_interface/SimpleTransmission</type>
        <joint name="e_2j">
            <hardwareInterface>hardware_interface/EffortJointInterface</hardwareInterface>
        </joint>
        <actuator name="e_2j_motor">
            <hardwareInterface>hardware_interface/EffortJointInterface</hardwareInterface>
            <mechanicalReduction>1</mechanicalReduction>
        </actuator>
    </transmission>
    <transmission name="trans_roll_2j">
        <type>transmission_interface/SimpleTransmission</type>
        <joint name="roll_2j">
            <hardwareInterface>hardware_interface/EffortJointInterface</hardwareInterface>
        </joint>
        <actuator name="roll_2j_motor">
            <hardwareInterface>hardware_interface/EffortJointInterface</hardwareInterface>
            <mechanicalReduction>1</mechanicalReduction>
        </actuator>
    </transmission>
    <transmission name="trans_pitch_2j">
        <type>transmission_interface/SimpleTransmission</type>
        <joint name="pitch_2j">
            <hardwareInterface>hardware_interface/EffortJointInterface</hardwareInterface>
        </joint>
        <actuator name="pitch_2j_motor">
            <hardwareInterface>hardware_interface/EffortJointInterface</hardwareInterface>
            <mechanicalReduction>1</mechanicalReduction>
        </actuator>
    </transmission>
</robot>

