<?xml version="1.0" encoding="utf-8"?>
<!-- This URDF was automatically created by SolidWorks to URDF Exporter! Originally created by Stephen Brawner (brawner@gmail.com) 
     Commit Version: 1.6.0-4-g7f85cfe  Build Version: 1.6.7995.38578
     For more information, please see http://wiki.ros.org/sw_urdf_exporter -->
<robot
  name="urdf">
  <link
    name="base_link">
    <inertial>
      <origin
        xyz="0.000160852559340272 0.416511988266863 0.00522519390962018"
        rpy="0 0 0" />
      <mass
        value="6.60658072927865" />
      <inertia
        ixx="0.205461268695088"
        ixy="-4.8631130134879E-08"
        ixz="3.31309244336347E-09"
        iyy="0.0632251395598791"
        iyz="-4.46121098307276E-09"
        izz="0.213924141252687" />
    </inertial>
    <visual>
      <origin
        xyz="0 0 0"
        rpy="0 0 0" />
      <geometry>
        <mesh
          filename="package://air_description/meshes/base_link.STL" />
      </geometry>
      <material
        name="">
        <color
          rgba="0.792156862745098 0.819607843137255 0.933333333333333 1" />
      </material>
    </visual>
    <collision>
      <origin
        xyz="0 0 0"
        rpy="0 0 0" />
      <geometry>
        <mesh
          filename="package://air_description/meshes/base_link.STL" />
      </geometry>
    </collision>
  </link>
  <link
    name="s1">
    <inertial>
      <origin
        xyz="-0.0565855661773653 -1.47432999124675E-05 0.0503451976338493"
        rpy="0 0 0" />
      <mass
        value="0.542684124579144" />
      <inertia
        ixx="0.000345761092952399"
        ixy="-3.24050500600486E-07"
        ixz="1.50683178516403E-07"
        iyy="0.000778022471193682"
        iyz="1.07326375799424E-08"
        izz="0.000776671252305068" />
    </inertial>
    <visual>
      <origin
        xyz="0 0 0"
        rpy="0 0 0" />
      <geometry>
        <mesh
          filename="package://air_description/meshes/s1.STL" />
      </geometry>
      <material
        name="">
        <color
          rgba="0.792156862745098 0.819607843137255 0.933333333333333 1" />
      </material>
    </visual>
    <collision>
      <origin
        xyz="0 0 0"
        rpy="0 0 0" />
      <geometry>
        <mesh
          filename="package://air_description/meshes/s1.STL" />
      </geometry>
    </collision>
  </link>
  <joint
    name="s1j"
    type="revolute">
    <origin
      xyz="0 -0.1455 1.1455"
      rpy="1.5708 0 0" />
    <parent
      link="base_link" />
    <child
      link="s1" />
    <axis
      xyz="0 0 1" />
    <limit
      lower="-0.78"
      upper="0.78"
      effort="0"
      velocity="0.35" />
  </joint>
  <link
    name="s2">
    <inertial>
      <origin
        xyz="0.0265368019978267 -0.0360762146328593 0.00202591662662588"
        rpy="0 0 0" />
      <mass
        value="0.0397003268136184" />
      <inertia
        ixx="1.77539568949169E-05"
        ixy="-5.49265597337707E-08"
        ixz="4.46961963342789E-21"
        iyy="9.62749691816005E-06"
        iyz="5.5659379414233E-21"
        izz="1.53865784423673E-05" />
    </inertial>
    <visual>
      <origin
        xyz="0 0 0"
        rpy="0 0 0" />
      <geometry>
        <mesh
          filename="package://air_description/meshes/s2.STL" />
      </geometry>
      <material
        name="">
        <color
          rgba="0.792156862745098 0.819607843137255 0.933333333333333 1" />
      </material>
    </visual>
    <collision>
      <origin
        xyz="0 0 0"
        rpy="0 0 0" />
      <geometry>
        <mesh
          filename="package://air_description/meshes/s2.STL" />
      </geometry>
    </collision>
  </link>
  <joint
    name="s2j"
    type="revolute">
    <origin
      xyz="0 0 0.05"
      rpy="0 0 0" />
    <parent
      link="s1" />
    <child
      link="s2" />
    <axis
      xyz="-1 0 0" />
    <limit
      lower="0"
      upper="1.57"
      effort="0"
      velocity="0.35" />
  </joint>
  <link
    name="s3">
    <inertial>
      <origin
        xyz="-0.0307852686146159 -0.106762715233885 -0.00285680761161178"
        rpy="0 0 0" />
      <mass
        value="0.69346525440976" />
      <inertia
        ixx="0.000632226154715784"
        ixy="3.3846916742775E-06"
        ixz="-2.03216958615076E-06"
        iyy="0.000203793561582271"
        iyz="-7.69131798756883E-08"
        izz="0.000626858789980171" />
    </inertial>
    <visual>
      <origin
        xyz="0 0 0"
        rpy="0 0 0" />
      <geometry>
        <mesh
          filename="package://air_description/meshes/s3.STL" />
      </geometry>
      <material
        name="">
        <color
          rgba="0.792156862745098 0.819607843137255 0.933333333333333 1" />
      </material>
    </visual>
    <collision>
      <origin
        xyz="0 0 0"
        rpy="0 0 0" />
      <geometry>
        <mesh
          filename="package://air_description/meshes/s3.STL" />
      </geometry>
    </collision>
  </link>
  <joint
    name="s3j"
    type="revolute">
    <origin
      xyz="-0.00345 -0.06 0.0036"
      rpy="0 0 0" />
    <parent
      link="s2" />
    <child
      link="s3" />
    <axis
      xyz="0 -1 0" />
    <limit
      lower="-1.57"
      upper="1.57"
      effort="0"
      velocity="0.35" />
  </joint>
  <link
    name="e">
    <inertial>
      <origin
        xyz="0.133914313079551 0.0397090138567681 -0.00135370354868536"
        rpy="0 0 0" />
      <mass
        value="0.524484949455585" />
      <inertia
        ixx="0.000164098535625993"
        ixy="-0.00011555456704967"
        ixz="-1.49937999308697E-06"
        iyy="0.000491486729879123"
        iyz="5.4210279008361E-06"
        izz="0.000537801635705856" />
    </inertial>
    <visual>
      <origin
        xyz="0 0 0"
        rpy="0 0 0" />
      <geometry>
        <mesh
          filename="package://air_description/meshes/e.STL" />
      </geometry>
      <material
        name="">
        <color
          rgba="0.792156862745098 0.819607843137255 0.933333333333333 1" />
      </material>
    </visual>
    <collision>
      <origin
        xyz="0 0 0"
        rpy="0 0 0" />
      <geometry>
        <mesh
          filename="package://air_description/meshes/e.STL" />
      </geometry>
    </collision>
  </link>
  <joint
    name="ej"
    type="revolute">
    <origin
      xyz="-0.005 -0.2835 0"
      rpy="0 0 -0.28935" />
    <parent
      link="s3" />
    <child
      link="e" />
    <axis
      xyz="0 0 1" />
    <limit
      lower="-1.4"
      upper="0.184"
      effort="0"
      velocity="0.13" />
  </joint>
  <link
    name="roll">
    <inertial>
      <origin
        xyz="2.11649564541005E-08 2.17253527112771E-08 -5.72361158468482E-10"
        rpy="0 0 0" />
      <mass
        value="0.0123350072540482" />
      <inertia
        ixx="5.73140316108075E-06"
        ixy="2.39610064059149E-12"
        ixz="2.37221429275288E-12"
        iyy="3.0133459248538E-06"
        iyz="-2.51281711383088E-12"
        izz="3.01335111374677E-06" />
    </inertial>
    <visual>
      <origin
        xyz="0 0 0"
        rpy="0 0 0" />
      <geometry>
        <mesh
          filename="package://air_description/meshes/roll.STL" />
      </geometry>
      <material
        name="">
        <color
          rgba="0.792156862745098 0.819607843137255 0.933333333333333 1" />
      </material>
    </visual>
    <collision>
      <origin
        xyz="0 0 0"
        rpy="0 0 0" />
      <geometry>
        <mesh
          filename="package://air_description/meshes/roll.STL" />
      </geometry>
    </collision>
  </link>
  <joint
    name="rollj"
    type="revolute">
    <origin
      xyz="0.25159 0.0749 0"
      rpy="-1.5708 0 -2.8522" />
    <parent
      link="e" />
    <child
      link="roll" />
    <axis
      xyz="0 0.70711 0.70711" />
    <limit
      lower="-0.26"
      upper="0.26"
      effort="0"
      velocity="0.09" />
  </joint>
  <link
    name="pitch">
    <inertial>
      <origin
        xyz="0.0286089165171641 -0.000144661566694015 0.009855465038871"
        rpy="0 0 0" />
      <mass
        value="0.0576090249075869" />
      <inertia
        ixx="7.09168260696957E-05"
        ixy="-9.04854271559607E-09"
        ixz="-9.02484498992207E-09"
        iyy="3.68466285330398E-05"
        iyz="-3.7654782496613E-07"
        izz="3.68466243102646E-05" />
    </inertial>
    <visual>
      <origin
        xyz="0 0 0"
        rpy="0 0 0" />
      <geometry>
        <mesh
          filename="package://air_description/meshes/pitch.STL" />
      </geometry>
      <material
        name="">
        <color
          rgba="0.792156862745098 0.819607843137255 0.933333333333333 1" />
      </material>
    </visual>
    <collision>
      <origin
        xyz="0 0 0"
        rpy="0 0 0" />
      <geometry>
        <mesh
          filename="package://air_description/meshes/pitch.STL" />
      </geometry>
    </collision>
  </link>
  <joint
    name="pitchj"
    type="revolute">
    <origin
      xyz="0 0.01 0"
      rpy="-1.5708 0 3.1416" />
    <parent
      link="roll" />
    <child
      link="pitch" />
    <axis
      xyz="0 0.70711 -0.70711" />
    <limit
      lower="-0.26"
      upper="0.26"
      effort="0"
      velocity="0.09" />
  </joint>
  <link
    name="yaw">
    <inertial>
      <origin
        xyz="0.121145515511824 -0.00274393412138674 -0.00280619674961233"
        rpy="0 0 0" />
      <mass
        value="0.288045639627102" />
      <inertia
        ixx="0.000166764800385917"
        ixy="1.15318815602555E-05"
        ixz="-2.72502292894343E-07"
        iyy="0.000292613552431781"
        iyz="3.6036191451638E-08"
        izz="0.000214965635544534" />
    </inertial>
    <visual>
      <origin
        xyz="0 0 0"
        rpy="0 0 0" />
      <geometry>
        <mesh
          filename="package://air_description/meshes/yaw.STL" />
      </geometry>
      <material
        name="">
        <color
          rgba="0.792156862745098 0.819607843137255 0.933333333333333 1" />
      </material>
    </visual>
    <collision>
      <origin
        xyz="0 0 0"
        rpy="0 0 0" />
      <geometry>
        <mesh
          filename="package://air_description/meshes/yaw.STL" />
      </geometry>
    </collision>
  </link>
  <joint
    name="yawj"
    type="revolute">
    <origin
      xyz="0.01 0 0.01"
      rpy="0 0 0" />
    <parent
      link="pitch" />
    <child
      link="yaw" />
    <axis
      xyz="-1 0 0" />
    <limit
      lower="-3.0"
      upper="3.0"
      effort="0"
      velocity="1.75" />
  </joint>

    <gazebo reference="base_link">
      <turnGravityOff>true</turnGravityOff>
    </gazebo>
    <gazebo reference="s1">
      <turnGravityOff>true</turnGravityOff>
    </gazebo>
    <gazebo reference="s2">
      <turnGravityOff>true</turnGravityOff>
    </gazebo>
    <gazebo reference="s3">
      <turnGravityOff>true</turnGravityOff>
    </gazebo>
    <gazebo reference="e">
      <turnGravityOff>true</turnGravityOff>
    </gazebo>
    <gazebo reference="roll">
      <turnGravityOff>true</turnGravityOff>
    </gazebo>
    <gazebo reference="pitch">
      <turnGravityOff>true</turnGravityOff>
    </gazebo>
    <gazebo reference="yaw">
      <turnGravityOff>true</turnGravityOff>
    </gazebo>

</robot>
